Workbook

Sheet Inputs
A1: FSF PRODUCTION PRICING — INPUTS
A2: How to use: edit BLUE numbers/text on this tab only. Yellow cells are blank and waiting for your number. Every cost on the costing tabs recalculates automatically. Empty rows are spare slots for new fabrics, styles and washes.
A4: FABRIC PRICES
A5: Fabric | B5: Price per yard ($) | C5: Notes
A6: 20oz Gabardine French Terry | B6: 8.57 | C6: From Fred, 9/30/2026
A7: Rib Knit | B7: 6.95 | C7: From Fred, 9/30/2026
A8: Jersey | B8: 3.95 | C8: From Fred, 9/30/2026
A9: Collar Rib (Tees) | B9: 3.95 | C9: From Fred, 9/30/2026
A10: Thermal | B10: 4.95 | C10: From Fred, 9/30/2026
A11: Nylon | C11: PRICE NEEDED — track jacket and track pants fabric. From Fred, 9/30/2026
A15: TRIMS PRICED BY THE YARD
A16: Trim | B16: Price per yard ($) | C16: Notes
A17: Drawstring | B17: 0.55 | C17: From Fred, 9/30/2026. Yards used per unit are set per style in the table below.
A18: Elastic | B18: 1 | C18: From Fred, 9/30/2026. Yards used per unit are set per style in the table below.
A20: STYLES — YIELDS & LABOR
A21: Style | B21: Wash price group | C21: Body fabric | D21: Body yield (yd per unit) | E21: Rib fabric | F21: Rib yield (yd per unit) | G21: Drawstring (yd per unit) | H21: Elastic (yd per unit) | I21: Sewing ($ per unit) | J21: Cutting ($ per unit) | K21: Distress grinding ($ per unit) | L21: Packaging ($ per unit) | M21: Trims / other ($ per unit) | N21: Notes
A22: Zip Hoodie | B22: Hoodies | C22: 20oz Gabardine French Terry | D22: 2.16 | E22: Rib Knit | F22: 0.75 | I22: 20 | J22: 1 | K22: 2.5 | L22: 3.5 | M22: 3 | N22: Standard hoodie: sewing $20 (the $30 price is kept as Specialized Zip Hoodie). Trims = zipper $3.00. No drawstring or elastic entered. From Fred, 9/30/2026
A23: Pullover Hoodie | B23: Hoodies | C23: 20oz Gabardine French Terry | D23: 2.06 | E23: Rib Knit | F23: 0.75 | I23: 15 | J23: 1 | K23: 2.5 | L23: 3.5 | N23: Standard hoodie: sewing $15 (the $25 price is kept as Specialized Pullover Hoodie). No drawstring or elastic entered. From Fred, 9/30/2026
A24: Specialized Zip Hoodie | B24: Hoodies | C24: 20oz Gabardine French Terry | D24: 2.16 | E24: Rib Knit | F24: 0.75 | I24: 30 | J24: 1 | K24: 2.5 | L24: 3.5 | M24: 3 | N24: Original hoodie pricing: sewing $30. Same yields, cutting, grinding and zipper as the Zip Hoodie. From Fred, 9/30/2026
A25: Specialized Pullover Hoodie | B25: Hoodies | C25: 20oz Gabardine French Terry | D25: 2.06 | E25: Rib Knit | F25: 0.75 | I25: 25 | J25: 1 | K25: 2.5 | L25: 3.5 | N25: Original hoodie pricing: sewing $25. Same yields, cutting and grinding as the Pullover Hoodie. From Fred, 9/30/2026
A26: Sweatpants | B26: Bottoms | C26: 20oz Gabardine French Terry | D26: 2.08 | G26: 2.25 | H26: 1.5 | I26: 18 | J26: 1 | K26: 2.5 | L26: 3.5 | N26: No rib entered. From Fred, 9/30/2026
A27: Sweat Shorts (Jorts Baggy Cut) | B27: Bottoms | C27: 20oz Gabardine French Terry | D27: 1.45 | G27: 2.25 | H27: 1.5 | I27: 16 | J27: 1 | K27: 2.5 | L27: 3.5 | N27: No rib entered. From Fred, 9/30/2026
A28: Short Sleeve Jersey Tee | B28: Tees | C28: Jersey | D28: 1.08 | E28: Collar Rib (Tees) | F28: 0.25 | I28: 10 | J28: 0.63 | L28: 3.5 | N28: Grinding not provided — counts as $0. From Fred, 9/30/2026
A29: Long Sleeve Jersey Tee | B29: Tees | C29: Jersey | D29: =D28+0.52 -> 1.6 | E29: Collar Rib (Tees) | F29: 0.25 | I29: 12 | J29: 1 | L29: 3.5 | N29: Body yield = short sleeve yield + 0.52 yd for sleeves. Grinding not provided — counts as $0. From Fred, 9/30/2026
A30: Thermal Long Sleeve | B30: Tees | C30: Thermal | D30: =D29 -> 1.6 | E30: Collar Rib (Tees) | F30: 0.25 | I30: =I29 -> 12 | J30: =J29 -> 1 | L30: 3.5 | N30: Body yield and wash prices same as long sleeve tee (from Fred). Sewing and cutting ASSUMED same as long sleeve tee — confirm. Grinding not provided — counts as $0.
A31: Tank Top | B31: Tees | C31: Rib Knit | D31: 0.75 | I31: 8 | J31: 0.95 | L31: 3.5 | N31: Body fabric = Rib Knit at $6.95 (fabric may change). No wash selected; tee wash prices apply if one is picked. From Fred, 10/1/2026
A32: Track Jacket | C32: Nylon | D32: 1.63 | I32: 60 | J32: =3.5+0.15 -> 3.65 | L32: 3.5 | M32: 3.9 | N32: Nylon price not provided yet — total excludes fabric. Cutting = jacket + lining $3.50 + fuse $0.15. Trims = zipper $3.90. From Fred, 9/30/2026
A33: Track Pants | C33: Nylon | D33: 1.4 | H33: 1.5 | I33: 20 | J33: 2 | L33: 3.5 | N33: Nylon price not provided yet — total excludes fabric. Elastic 1.5 yd ASSUMED same as sweatpants — confirm. From Fred, 9/30/2026
A38: Body/Rib fabric names must match the Fabric list above exactly. Leave Rib fabric and yield blank if a style has no rib.
A41: WASH / FINISH — COST PER UNIT BY PRODUCT GROUP ($)
A42: Wash | B42: Hoodies | C42: Bottoms | D42: Tees | F42: Notes
A43: PP Spray (Potassium) | B43: 23 | C43: 18 | D43: 12 | F43: From Fred, 9/30/2026
A44: Stone Wash | B44: 12 | C44: 11 | D44: 6 | F44: Bottoms = $1 less than hoodies. Tees revised from $4.75 to $6.00. From Fred, 9/30/2026
A45: Basic Wash / Dye | B45: 4.75 | C45: 3.75 | D45: 2.75 | F45: Bottoms = $1 less than hoodies. From Fred, 9/30/2026
A50: PRICING
A51: Lever | B51: Value | C51: Notes
A52: FSF markup % | B52: 0.2 | C52: From Fred, 9/30/2026. Cost incl. markup = total cost × (1 + markup). Applied to every style.
A53: Selling price multiple | B53: 2.5 | C53: From Fred, 9/30/2026. Selling price = total cost including FSF markup × this multiple.
A55: ONE-TIME FEES PER STYLE (charged once, not per garment)
A56: Fee | B56: Amount ($) | C56: Notes
...

Sheet Hoodies
A1: HOODIE COST PER UNIT
A2: Each column is one build. Pick a Style and Wash from the dropdowns (blue cells) — everything below is a formula pulling from the Inputs tab. Leave Wash blank for no wash. Green = pulled from Inputs, black = calculated.
A4: Style | B4: Zip Hoodie | C4: Zip Hoodie | D4: Zip Hoodie | E4: Pullover Hoodie | F4: Pullover Hoodie | G4: Pullover Hoodie | H4: Specialized Zip Hoodie | I4: Specialized Zip Hoodie | J4: Specialized Zip Hoodie | K4: Specialized Pullover Hoodie | L4: Specialized Pullover Hoodie | M4: Specialized Pullover Hoodie
A5: Wash | B5: PP Spray (Potassium) | C5: Stone Wash | D5: Basic Wash / Dye | E5: PP Spray (Potassium) | F5: Stone Wash | G5: Basic Wash / Dye | H5: PP Spray (Potassium) | I5: Stone Wash | J5: Basic Wash / Dye | K5: PP Spray (Potassium) | L5: Stone Wash | M5: Basic Wash / Dye
A6: BODY FABRIC
A7: Body fabric | B7: =IF(INDEX(Inputs!$C$22:$C$37,MATCH(B$4,Inputs!$A$22:$A$37,0))="","",INDEX(Inputs!$C$22:$C$37,MATCH(B$4,Inputs!$A$22:$A$37,0))) -> 20oz Gabardine French Terry | C7: =IF(INDEX(Inputs!$C$22:$C$37,MATCH(C$4,Inputs!$A$22:$A$37,0))="","",INDEX(Inputs!$C$22:$C$37,MATCH(C$4,Inputs!$A$22:$A$37,0))) -> 20oz Gabardine French Terry | D7: =IF(INDEX(Inputs!$C$22:$C$37,MATCH(D$4,Inputs!$A$22:$A$37,0))="","",INDEX(Inputs!$C$22:$C$37,MATCH(D$4,Inputs!$A$22:$A$37,0))) -> 20oz Gabardine French Terry | E7: =IF(INDEX(Inputs!$C$22:$C$37,MATCH(E$4,Inputs!$A$22:$A$37,0))="","",INDEX(Inputs!$C$22:$C$37,MATCH(E$4,Inputs!$A$22:$A$37,0))) -> 20oz Gabardine French Terry | F7: =IF(INDEX(Inputs!$C$22:$C$37,MATCH(F$4,Inputs!$A$22:$A$37,0))="","",INDEX(Inputs!$C$22:$C$37,MATCH(F$4,Inputs!$A$22:$A$37,0))) -> 20oz Gabardine French Terry | G7: =IF(INDEX(Inputs!$C$22:$C$37,MATCH(G$4,Inputs!$A$22:$A$37,0))="","",INDEX(Inputs!$C$22:$C$37,MATCH(G$4,Inputs!$A$22:$A$37,0))) -> 20oz Gabardine French Terry | H7: =IF(INDEX(Inputs!$C$22:$C$37,MATCH(H$4,Inputs!$A$22:$A$37,0))="","",INDEX(Inputs!$C$22:$C$37,MATCH(H$4,Inputs!$A$22:$A$37,0))) -> 20oz Gabardine French Terry | I7: =IF(INDEX(Inputs!$C$22:$C$37,MATCH(I$4,Inputs!$A$22:$A$37,0))="","",INDEX(Inputs!$C$22:$C$37,MATCH(I$4,Inputs!$A$22:$A$37,0))) -> 20oz Gabardine French Terry | ... M7: =IF(INDEX(Inputs!$C$22:$C$37,MATCH(M$4,Inputs!$A$22:$A$37,0))="","",INDEX(Inputs!$C$22:$C$37,MATCH(M$4,Inputs!$A$22:$A$37,0))) -> 20oz Gabardine French Terry
A8: Body yield (yd) | B8: =INDEX(Inputs!$D$22:$D$37,MATCH(B$4,Inputs!$A$22:$A$37,0)) -> 2.16 | C8: =INDEX(Inputs!$D$22:$D$37,MATCH(C$4,Inputs!$A$22:$A$37,0)) -> 2.16 | D8: =INDEX(Inputs!$D$22:$D$37,MATCH(D$4,Inputs!$A$22:$A$37,0)) -> 2.16 | E8: =INDEX(Inputs!$D$22:$D$37,MATCH(E$4,Inputs!$A$22:$A$37,0)) -> 2.06 | F8: =INDEX(Inputs!$D$22:$D$37,MATCH(F$4,Inputs!$A$22:$A$37,0)) -> 2.06 | G8: =INDEX(Inputs!$D$22:$D$37,MATCH(G$4,Inputs!$A$22:$A$37,0)) -> 2.06 | H8: =INDEX(Inputs!$D$22:$D$37,MATCH(H$4,Inputs!$A$22:$A$37,0)) -> 2.16 | I8: =INDEX(Inputs!$D$22:$D$37,MATCH(I$4,Inputs!$A$22:$A$37,0)) -> 2.16 | ... M8: =INDEX(Inputs!$D$22:$D$37,MATCH(M$4,Inputs!$A$22:$A$37,0)) -> 2.06
A9: Body fabric price ($/yd) | B9: =IF(B7="",0,INDEX(Inputs!$B$6:$B$13,MATCH(B7,Inputs!$A$6:$A$13,0))) -> 8.57 | C9: =IF(C7="",0,INDEX(Inputs!$B$6:$B$13,MATCH(C7,Inputs!$A$6:$A$13,0))) -> 8.57 | D9: =IF(D7="",0,INDEX(Inputs!$B$6:$B$13,MATCH(D7,Inputs!$A$6:$A$13,0))) -> 8.57 | E9: =IF(E7="",0,INDEX(Inputs!$B$6:$B$13,MATCH(E7,Inputs!$A$6:$A$13,0))) -> 8.57 | F9: =IF(F7="",0,INDEX(Inputs!$B$6:$B$13,MATCH(F7,Inputs!$A$6:$A$13,0))) -> 8.57 | G9: =IF(G7="",0,INDEX(Inputs!$B$6:$B$13,MATCH(G7,Inputs!$A$6:$A$13,0))) -> 8.57 | H9: =IF(H7="",0,INDEX(Inputs!$B$6:$B$13,MATCH(H7,Inputs!$A$6:$A$13,0))) -> 8.57 | I9: =IF(I7="",0,INDEX(Inputs!$B$6:$B$13,MATCH(I7,Inputs!$A$6:$A$13,0))) -> 8.57 | ... M9: =IF(M7="",0,INDEX(Inputs!$B$6:$B$13,MATCH(M7,Inputs!$A$6:$A$13,0))) -> 8.57
A10: Body fabric cost ($) | B10: =B8*B9 -> 18.5112 | C10: =C8*C9 -> 18.5112 | D10: =D8*D9 -> 18.5112 | E10: =E8*E9 -> 17.6542 | F10: =F8*F9 -> 17.6542 | G10: =G8*G9 -> 17.6542 | H10: =H8*H9 -> 18.5112 | I10: =I8*I9 -> 18.5112 | ... M10: =M8*M9 -> 17.6542
A11: RIB
A12: Rib fabric | B12: =IF(INDEX(Inputs!$E$22:$E$37,MATCH(B$4,Inputs!$A$22:$A$37,0))="","",INDEX(Inputs!$E$22:$E$37,MATCH(B$4,Inputs!$A$22:$A$37,0))) -> Rib Knit | C12: =IF(INDEX(Inputs!$E$22:$E$37,MATCH(C$4,Inputs!$A$22:$A$37,0))="","",INDEX(Inputs!$E$22:$E$37,MATCH(C$4,Inputs!$A$22:$A$37,0))) -> Rib Knit | D12: =IF(INDEX(Inputs!$E$22:$E$37,MATCH(D$4,Inputs!$A$22:$A$37,0))="","",INDEX(Inputs!$E$22:$E$37,MATCH(D$4,Inputs!$A$22:$A$37,0))) -> Rib Knit | E12: =IF(INDEX(Inputs!$E$22:$E$37,MATCH(E$4,Inputs!$A$22:$A$37,0))="","",INDEX(Inputs!$E$22:$E$37,MATCH(E$4,Inputs!$A$22:$A$37,0))) -> Rib Knit | F12: =IF(INDEX(Inputs!$E$22:$E$37,MATCH(F$4,Inputs!$A$22:$A$37,0))="","",INDEX(Inputs!$E$22:$E$37,MATCH(F$4,Inputs!$A$22:$A$37,0))) -> Rib Knit | G12: =IF(INDEX(Inputs!$E$22:$E$37,MATCH(G$4,Inputs!$A$22:$A$37,0))="","",INDEX(Inputs!$E$22:$E$37,MATCH(G$4,Inputs!$A$22:$A$37,0))) -> Rib Knit | H12: =IF(INDEX(Inputs!$E$22:$E$37,MATCH(H$4,Inputs!$A$22:$A$37,0))="","",INDEX(Inputs!$E$22:$E$37,MATCH(H$4,Inputs!$A$22:$A$37,0))) -> Rib Knit | I12: =IF(INDEX(Inputs!$E$22:$E$37,MATCH(I$4,Inputs!$A$22:$A$37,0))="","",INDEX(Inputs!$E$22:$E$37,MATCH(I$4,Inputs!$A$22:$A$37,0))) -> Rib Knit | ... M12: =IF(INDEX(Inputs!$E$22:$E$37,MATCH(M$4,Inputs!$A$22:$A$37,0))="","",INDEX(Inputs!$E$22:$E$37,MATCH(M$4,Inputs!$A$22:$A$37,0))) -> Rib Knit
A13: Rib yield (yd) | B13: =INDEX(Inputs!$F$22:$F$37,MATCH(B$4,Inputs!$A$22:$A$37,0)) -> 0.75 | C13: =INDEX(Inputs!$F$22:$F$37,MATCH(C$4,Inputs!$A$22:$A$37,0)) -> 0.75 | D13: =INDEX(Inputs!$F$22:$F$37,MATCH(D$4,Inputs!$A$22:$A$37,0)) -> 0.75 | E13: =INDEX(Inputs!$F$22:$F$37,MATCH(E$4,Inputs!$A$22:$A$37,0)) -> 0.75 | F13: =INDEX(Inputs!$F$22:$F$37,MATCH(F$4,Inputs!$A$22:$A$37,0)) -> 0.75 | G13: =INDEX(Inputs!$F$22:$F$37,MATCH(G$4,Inputs!$A$22:$A$37,0)) -> 0.75 | H13: =INDEX(Inputs!$F$22:$F$37,MATCH(H$4,Inputs!$A$22:$A$37,0)) -> 0.75 | I13: =INDEX(Inputs!$F$22:$F$37,MATCH(I$4,Inputs!$A$22:$A$37,0)) -> 0.75 | ... M13: =INDEX(Inputs!$F$22:$F$37,MATCH(M$4,Inputs!$A$22:$A$37,0)) -> 0.75
A14: Rib price ($/yd) | B14: =IF(B12="",0,INDEX(Inputs!$B$6:$B$13,MATCH(B12,Inputs!$A$6:$A$13,0))) -> 6.95 | C14: =IF(C12="",0,INDEX(Inputs!$B$6:$B$13,MATCH(C12,Inputs!$A$6:$A$13,0))) -> 6.95 | D14: =IF(D12="",0,INDEX(Inputs!$B$6:$B$13,MATCH(D12,Inputs!$A$6:$A$13,0))) -> 6.95 | E14: =IF(E12="",0,INDEX(Inputs!$B$6:$B$13,MATCH(E12,Inputs!$A$6:$A$13,0))) -> 6.95 | F14: =IF(F12="",0,INDEX(Inputs!$B$6:$B$13,MATCH(F12,Inputs!$A$6:$A$13,0))) -> 6.95 | G14: =IF(G12="",0,INDEX(Inputs!$B$6:$B$13,MATCH(G12,Inputs!$A$6:$A$13,0))) -> 6.95 | H14: =IF(H12="",0,INDEX(Inputs!$B$6:$B$13,MATCH(H12,Inputs!$A$6:$A$13,0))) -> 6.95 | I14: =IF(I12="",0,INDEX(Inputs!$B$6:$B$13,MATCH(I12,Inputs!$A$6:$A$13,0))) -> 6.95 | ... M14: =IF(M12="",0,INDEX(Inputs!$B$6:$B$13,MATCH(M12,Inputs!$A$6:$A$13,0))) -> 6.95
A15: Rib cost ($) | B15: =B13*B14 -> 5.2125 | C15: =C13*C14 -> 5.2125 | D15: =D13*D14 -> 5.2125 | E15: =E13*E14 -> 5.2125 | F15: =F13*F14 -> 5.2125 | G15: =G13*G14 -> 5.2125 | H15: =H13*H14 -> 5.2125 | I15: =I13*I14 -> 5.2125 | ... M15: =M13*M14 -> 5.2125
A16: DRAWSTRING & ELASTIC
A17: Drawstring (yd) | B17: =INDEX(Inputs!$G$22:$G$37,MATCH(B$4,Inputs!$A$22:$A$37,0)) -> 0 | C17: =INDEX(Inputs!$G$22:$G$37,MATCH(C$4,Inputs!$A$22:$A$37,0)) -> 0 | D17: =INDEX(Inputs!$G$22:$G$37,MATCH(D$4,Inputs!$A$22:$A$37,0)) -> 0 | E17: =INDEX(Inputs!$G$22:$G$37,MATCH(E$4,Inputs!$A$22:$A$37,0)) -> 0 | F17: =INDEX(Inputs!$G$22:$G$37,MATCH(F$4,Inputs!$A$22:$A$37,0)) -> 0 | G17: =INDEX(Inputs!$G$22:$G$37,MATCH(G$4,Inputs!$A$22:$A$37,0)) -> 0 | H17: =INDEX(Inputs!$G$22:$G$37,MATCH(H$4,Inputs!$A$22:$A$37,0)) -> 0 | I17: =INDEX(Inputs!$G$22:$G$37,MATCH(I$4,Inputs!$A$22:$A$37,0)) -> 0 | ... M17: =INDEX(Inputs!$G$22:$G$37,MATCH(M$4,Inputs!$A$22:$A$37,0)) -> 0
A18: Drawstring price ($/yd) | B18: =Inputs!$B$17 -> 0.55 | C18: =Inputs!$B$17 -> 0.55 | D18: =Inputs!$B$17 -> 0.55 | E18: =Inputs!$B$17 -> 0.55 | F18: =Inputs!$B$17 -> 0.55 | G18: =Inputs!$B$17 -> 0.55 | H18: =Inputs!$B$17 -> 0.55 | I18: =Inputs!$B$17 -> 0.55 | ... M18: =Inputs!$B$17 -> 0.55
A19: Drawstring cost ($) | B19: =B17*B18 -> 0 | C19: =C17*C18 -> 0 | D19: =D17*D18 -> 0 | E19: =E17*E18 -> 0 | F19: =F17*F18 -> 0 | G19: =G17*G18 -> 0 | H19: =H17*H18 -> 0 | I19: =I17*I18 -> 0 | ... M19: =M17*M18 -> 0
A20: Elastic (yd) | B20: =INDEX(Inputs!$H$22:$H$37,MATCH(B$4,Inputs!$A$22:$A$37,0)) -> 0 | C20: =INDEX(Inputs!$H$22:$H$37,MATCH(C$4,Inputs!$A$22:$A$37,0)) -> 0 | D20: =INDEX(Inputs!$H$22:$H$37,MATCH(D$4,Inputs!$A$22:$A$37,0)) -> 0 | E20: =INDEX(Inputs!$H$22:$H$37,MATCH(E$4,Inputs!$A$22:$A$37,0)) -> 0 | F20: =INDEX(Inputs!$H$22:$H$37,MATCH(F$4,Inputs!$A$22:$A$37,0)) -> 0 | G20: =INDEX(Inputs!$H$22:$H$37,MATCH(G$4,Inputs!$A$22:$A$37,0)) -> 0 | H20: =INDEX(Inputs!$H$22:$H$37,MATCH(H$4,Inputs!$A$22:$A$37,0)) -> 0 | I20: =INDEX(Inputs!$H$22:$H$37,MATCH(I$4,Inputs!$A$22:$A$37,0)) -> 0 | ... M20: =INDEX(Inputs!$H$22:$H$37,MATCH(M$4,Inputs!$A$22:$A$37,0)) -> 0
A21: Elastic price ($/yd) | B21: =Inputs!$B$18 -> 1 | C21: =Inputs!$B$18 -> 1 | D21: =Inputs!$B$18 -> 1 | E21: =Inputs!$B$18 -> 1 | F21: =Inputs!$B$18 -> 1 | G21: =Inputs!$B$18 -> 1 | H21: =Inputs!$B$18 -> 1 | I21: =Inputs!$B$18 -> 1 | ... M21: =Inputs!$B$18 -> 1
A22: Elastic cost ($) | B22: =B20*B21 -> 0 | C22: =C20*C21 -> 0 | D22: =D20*D21 -> 0 | E22: =E20*E21 -> 0 | F22: =F20*F21 -> 0 | G22: =G20*G21 -> 0 | H22: =H20*H21 -> 0 | I22: =I20*I21 -> 0 | ... M22: =M20*M21 -> 0
A23: WASH, LABOR, TRIMS & PACKAGING
A24: Wash cost ($) | B24: =IF(B5="",0,INDEX(Inputs!$B$43:$E$48,MATCH(B5,Inputs!$A$43:$A$48,0),MATCH(INDEX(Inputs!$B$22:$B$37,MATCH(B$4,Inputs!$A$22:$A$37,0)),Inputs!$B$42:$E$42,0))) -> 23 | C24: =IF(C5="",0,INDEX(Inputs!$B$43:$E$48,MATCH(C5,Inputs!$A$43:$A$48,0),MATCH(INDEX(Inputs!$B$22:$B$37,MATCH(C$4,Inputs!$A$22:$A$37,0)),Inputs!$B$42:$E$42,0))) -> 12 | D24: =IF(D5="",0,INDEX(Inputs!$B$43:$E$48,MATCH(D5,Inputs!$A$43:$A$48,0),MATCH(INDEX(Inputs!$B$22:$B$37,MATCH(D$4,Inputs!$A$22:$A$37,0)),Inputs!$B$42:$E$42,0))) -> 4.75 | E24: =IF(E5="",0,INDEX(Inputs!$B$43:$E$48,MATCH(E5,Inputs!$A$43:$A$48,0),MATCH(INDEX(Inputs!$B$22:$B$37,MATCH(E$4,Inputs!$A$22:$A$37,0)),Inputs!$B$42:$E$42,0))) -> 23 | F24: =IF(F5="",0,INDEX(Inputs!$B$43:$E$48,MATCH(F5,Inputs!$A$43:$A$48,0),MATCH(INDEX(Inputs!$B$22:$B$37,MATCH(F$4,Inputs!$A$22:$A$37,0)),Inputs!$B$42:$E$42,0))) -> 12 | G24: =IF(G5="",0,INDEX(Inputs!$B$43:$E$48,MATCH(G5,Inputs!$A$43:$A$48,0),MATCH(INDEX(Inputs!$B$22:$B$37,MATCH(G$4,Inputs!$A$22:$A$37,0)),Inputs!$B$42:$E$42,0))) -> 4.75 | H24: =IF(H5="",0,INDEX(Inputs!$B$43:$E$48,MATCH(H5,Inputs!$A$43:$A$48,0),MATCH(INDEX(Inputs!$B$22:$B$37,MATCH(H$4,Inputs!$A$22:$A$37,0)),Inputs!$B$42:$E$42,0))) -> 23 | I24: =IF(I5="",0,INDEX(Inputs!$B$43:$E$48,MATCH(I5,Inputs!$A$43:$A$48,0),MATCH(INDEX(Inputs!$B$22:$B$37,MATCH(I$4,Inputs!$A$22:$A$37,0)),Inputs!$B$42:$E$42,0))) -> 12 | ... M24: =IF(M5="",0,INDEX(Inputs!$B$43:$E$48,MATCH(M5,Inputs!$A$43:$A$48,0),MATCH(INDEX(Inputs!$B$22:$B$37,MATCH(M$4,Inputs!$A$22:$A$37,0)),Inputs!$B$42:$E$42,0))) -> 4.75
A25: Distress grinding ($) | B25: =INDEX(Inputs!$K$22:$K$37,MATCH(B$4,Inputs!$A$22:$A$37,0)) -> 2.5 | C25: =INDEX(Inputs!$K$22:$K$37,MATCH(C$4,Inputs!$A$22:$A$37,0)) -> 2.5 | D25: =INDEX(Inputs!$K$22:$K$37,MATCH(D$4,Inputs!$A$22:$A$37,0)) -> 2.5 | E25: =INDEX(Inputs!$K$22:$K$37,MATCH(E$4,Inputs!$A$22:$A$37,0)) -> 2.5 | F25: =INDEX(Inputs!$K$22:$K$37,MATCH(F$4,Inputs!$A$22:$A$37,0)) -> 2.5 | G25: =INDEX(Inputs!$K$22:$K$37,MATCH(G$4,Inputs!$A$22:$A$37,0)) -> 2.5 | H25: =INDEX(Inputs!$K$22:$K$37,MATCH(H$4,Inputs!$A$22:$A$37,0)) -> 2.5 | I25: =INDEX(Inputs!$K$22:$K$37,MATCH(I$4,Inputs!$A$22:$A$37,0)) -> 2.5 | ... M25: =INDEX(Inputs!$K$22:$K$37,MATCH(M$4,Inputs!$A$22:$A$37,0)) -> 2.5
A26: Cutting ($) | B26: =INDEX(Inputs!$J$22:$J$37,MATCH(B$4,Inputs!$A$22:$A$37,0)) -> 1 | C26: =INDEX(Inputs!$J$22:$J$37,MATCH(C$4,Inputs!$A$22:$A$37,0)) -> 1 | D26: =INDEX(Inputs!$J$22:$J$37,MATCH(D$4,Inputs!$A$22:$A$37,0)) -> 1 | E26: =INDEX(Inputs!$J$22:$J$37,MATCH(E$4,Inputs!$A$22:$A$37,0)) -> 1 | F26: =INDEX(Inputs!$J$22:$J$37,MATCH(F$4,Inputs!$A$22:$A$37,0)) -> 1 | G26: =INDEX(Inputs!$J$22:$J$37,MATCH(G$4,Inputs!$A$22:$A$37,0)) -> 1 | H26: =INDEX(Inputs!$J$22:$J$37,MATCH(H$4,Inputs!$A$22:$A$37,0)) -> 1 | I26: =INDEX(Inputs!$J$22:$J$37,MATCH(I$4,Inputs!$A$22:$A$37,0)) -> 1 | ... M26: =INDEX(Inputs!$J$22:$J$37,MATCH(M$4,Inputs!$A$22:$A$37,0)) -> 1
A27: Sewing ($) | B27: =INDEX(Inputs!$I$22:$I$37,MATCH(B$4,Inputs!$A$22:$A$37,0)) -> 20 | C27: =INDEX(Inputs!$I$22:$I$37,MATCH(C$4,Inputs!$A$22:$A$37,0)) -> 20 | D27: =INDEX(Inputs!$I$22:$I$37,MATCH(D$4,Inputs!$A$22:$A$37,0)) -> 20 | E27: =INDEX(Inputs!$I$22:$I$37,MATCH(E$4,Inputs!$A$22:$A$37,0)) -> 15 | F27: =INDEX(Inputs!$I$22:$I$37,MATCH(F$4,Inputs!$A$22:$A$37,0)) -> 15 | G27: =INDEX(Inputs!$I$22:$I$37,MATCH(G$4,Inputs!$A$22:$A$37,0)) -> 15 | H27: =INDEX(Inputs!$I$22:$I$37,MATCH(H$4,Inputs!$A$22:$A$37,0)) -> 30 | I27: =INDEX(Inputs!$I$22:$I$37,MATCH(I$4,Inputs!$A$22:$A$37,0)) -> 30 | ... M27: =INDEX(Inputs!$I$22:$I$37,MATCH(M$4,Inputs!$A$22:$A$37,0)) -> 25
A28: Trims / other ($) | B28: =INDEX(Inputs!$M$22:$M$37,MATCH(B$4,Inputs!$A$22:$A$37,0)) -> 3 | C28: =INDEX(Inputs!$M$22:$M$37,MATCH(C$4,Inputs!$A$22:$A$37,0)) -> 3 | D28: =INDEX(Inputs!$M$22:$M$37,MATCH(D$4,Inputs!$A$22:$A$37,0)) -> 3 | E28: =INDEX(Inputs!$M$22:$M$37,MATCH(E$4,Inputs!$A$22:$A$37,0)) -> 0 | F28: =INDEX(Inputs!$M$22:$M$37,MATCH(F$4,Inputs!$A$22:$A$37,0)) -> 0 | G28: =INDEX(Inputs!$M$22:$M$37,MATCH(G$4,Inputs!$A$22:$A$37,0)) -> 0 | H28: =INDEX(Inputs!$M$22:$M$37,MATCH(H$4,Inputs!$A$22:$A$37,0)) -> 3 | I28: =INDEX(Inputs!$M$22:$M$37,MATCH(I$4,Inputs!$A$22:$A$37,0)) -> 3 | ... M28: =INDEX(Inputs!$M$22:$M$37,MATCH(M$4,Inputs!$A$22:$A$37,0)) -> 0
A29: Packaging ($) | B29: =INDEX(Inputs!$L$22:$L$37,MATCH(B$4,Inputs!$A$22:$A$37,0)) -> 3.5 | C29: =INDEX(Inputs!$L$22:$L$37,MATCH(C$4,Inputs!$A$22:$A$37,0)) -> 3.5 | D29: =INDEX(Inputs!$L$22:$L$37,MATCH(D$4,Inputs!$A$22:$A$37,0)) -> 3.5 | E29: =INDEX(Inputs!$L$22:$L$37,MATCH(E$4,Inputs!$A$22:$A$37,0)) -> 3.5 | F29: =INDEX(Inputs!$L$22:$L$37,MATCH(F$4,Inputs!$A$22:$A$37,0)) -> 3.5 | G29: =INDEX(Inputs!$L$22:$L$37,MATCH(G$4,Inputs!$A$22:$A$37,0)) -> 3.5 | H29: =INDEX(Inputs!$L$22:$L$37,MATCH(H$4,Inputs!$A$22:$A$37,0)) -> 3.5 | I29: =INDEX(Inputs!$L$22:$L$37,MATCH(I$4,Inputs!$A$22:$A$37,0)) -> 3.5 | ... M29: =INDEX(Inputs!$L$22:$L$37,MATCH(M$4,Inputs!$A$22:$A$37,0)) -> 3.5
A31: TOTAL COST PER UNIT ($) | B31: =B10+B15+B19+B22+B24+B25+B26+B27+B28+B29 -> 76.7237 | C31: =C10+C15+C19+C22+C24+C25+C26+C27+C28+C29 -> 65.7237 | D31: =D10+D15+D19+D22+D24+D25+D26+D27+D28+D29 -> 58.4737 | E31: =E10+E15+E19+E22+E24+E25+E26+E27+E28+E29 -> 67.8667 | F31: =F10+F15+F19+F22+F24+F25+F26+F27+F28+F29 -> 56.8667 | G31: =G10+G15+G19+G22+G24+G25+G26+G27+G28+G29 -> 49.6167 | H31: =H10+H15+H19+H22+H24+H25+H26+H27+H28+H29 -> 86.7237 | I31: =I10+I15+I19+I22+I24+I25+I26+I27+I28+I29 -> 75.7237 | ... M31: =M10+M15+M19+M22+M24+M25+M26+M27+M28+M29 -> 59.6167
A32: Status | B32: =IF(B7="","NO FABRIC SET — total excludes fabric",IF(B8=0,"MISSING YIELD — fabric not in total",IF(B9=0,"MISSING FABRIC PRICE — fabric not in total",IF(AND(B12<>"",B13=0),"MISSING RIB YIELD — rib not in total","Complete")))) -> Complete | C32: =IF(C7="","NO FABRIC SET — total excludes fabric",IF(C8=0,"MISSING YIELD — fabric not in total",IF(C9=0,"MISSING FABRIC PRICE — fabric not in total",IF(AND(C12<>"",C13=0),"MISSING RIB YIELD — rib not in total","Complete")))) -> Complete | D32: =IF(D7="","NO FABRIC SET — total excludes fabric",IF(D8=0,"MISSING YIELD — fabric not in total",IF(D9=0,"MISSING FABRIC PRICE — fabric not in total",IF(AND(D12<>"",D13=0),"MISSING RIB YIELD — rib not in total","Complete")))) -> Complete | E32: =IF(E7="","NO FABRIC SET — total excludes fabric",IF(E8=0,"MISSING YIELD — fabric not in total",IF(E9=0,"MISSING FABRIC PRICE — fabric not in total",IF(AND(E12<>"",E13=0),"MISSING RIB YIELD — rib not in total","Complete")))) -> Complete | F32: =IF(F7="","NO FABRIC SET — total excludes fabric",IF(F8=0,"MISSING YIELD — fabric not in total",IF(F9=0,"MISSING FABRIC PRICE — fabric not in total",IF(AND(F12<>"",F13=0),"MISSING RIB YIELD — rib not in total","Complete")))) -> Complete | G32: =IF(G7="","NO FABRIC SET — total excludes fabric",IF(G8=0,"MISSING YIELD — fabric not in total",IF(G9=0,"MISSING FABRIC PRICE — fabric not in total",IF(AND(G12<>"",G13=0),"MISSING RIB YIELD — rib not in total","Complete")))) -> Complete | H32: =IF(H7="","NO FABRIC SET — total excludes fabric",IF(H8=0,"MISSING YIELD — fabric not in total",IF(H9=0,"MISSING FABRIC PRICE — fabric not in total",IF(AND(H12<>"",H13=0),"MISSING RIB YIELD — rib not in total","Complete")))) -> Complete | I32: =IF(I7="","NO FABRIC SET — total excludes fabric",IF(I8=0,"MISSING YIELD — fabric not in total",IF(I9=0,"MISSING FABRIC PRICE — fabric not in total",IF(AND(I12<>"",I13=0),"MISSING RIB YIELD — rib not in total","Complete")))) -> Complete | ... M32: =IF(M7="","NO FABRIC SET — total excludes fabric",IF(M8=0,"MISSING YIELD — fabric not in total",IF(M9=0,"MISSING FABRIC PRICE — fabric not in total",IF(AND(M12<>"",M13=0),"MISSING RIB YIELD — rib not in total","Complete")))) -> Complete
A33: PRICING
A34: FSF markup % | B34: =Inputs!$B$52 -> 0.2 | C34: =Inputs!$B$52 -> 0.2 | D34: =Inputs!$B$52 -> 0.2 | E34: =Inputs!$B$52 -> 0.2 | F34: =Inputs!$B$52 -> 0.2 | G34: =Inputs!$B$52 -> 0.2 | H34: =Inputs!$B$52 -> 0.2 | I34: =Inputs!$B$52 -> 0.2 | ... M34: =Inputs!$B$52 -> 0.2
A35: FSF markup ($) | B35: =B31*B34 -> 15.34474 | C35: =C31*C34 -> 13.14474 | D35: =D31*D34 -> 11.69474 | E35: =E31*E34 -> 13.57334 | F35: =F31*F34 -> 11.37334 | G35: =G31*G34 -> 9.92334 | H35: =H31*H34 -> 17.34474 | I35: =I31*I34 -> 15.14474 | ... M35: =M31*M34 -> 11.92334
A36: TOTAL COST INCL. FSF MARKUP ($) | B36: =B31+B35 -> 92.06844 | C36: =C31+C35 -> 78.86844 | D36: =D31+D35 -> 70.16844 | E36: =E31+E35 -> 81.44004 | F36: =F31+F35 -> 68.24004 | G36: =G31+G35 -> 59.54004 | H36: =H31+H35 -> 104.06844 | I36: =I31+I35 -> 90.86844 | ... M36: =M31+M35 -> 71.54004
A37: Selling price multiple | B37: =Inputs!$B$53 -> 2.5 | C37: =Inputs!$B$53 -> 2.5 | D37: =Inputs!$B$53 -> 2.5 | E37: =Inputs!$B$53 -> 2.5 | F37: =Inputs!$B$53 -> 2.5 | G37: =Inputs!$B$53 -> 2.5 | H37: =Inputs!$B$53 -> 2.5 | I37: =Inputs!$B$53 -> 2.5 | ... M37: =Inputs!$B$53 -> 2.5
A38: SELLING PRICE PER UNIT ($) | B38: =B36*B37 -> 230.1711 | C38: =C36*C37 -> 197.1711 | D38: =D36*D37 -> 175.4211 | E38: =E36*E37 -> 203.6001 | F38: =F36*F37 -> 170.6001 | G38: =G36*G37 -> 148.8501 | H38: =H36*H37 -> 260.1711 | I38: =I36*I37 -> 227.1711 | ... M38: =M36*M37 -> 178.8501
A40: ONE-TIME FEES — charged once per style, not per garment or per wash; not in unit cost or selling price
A41: Pattern fee ($) | B41: =Inputs!$B$57 -> 200 | C41: =Inputs!$B$57 -> 200 | D41: =Inputs!$B$57 -> 200 | E41: =Inputs!$B$57 -> 200 | F41: =Inputs!$B$57 -> 200 | G41: =Inputs!$B$57 -> 200 | H41: =Inputs!$B$57 -> 200 | I41: =Inputs!$B$57 -> 200 | ... M41: =Inputs!$B$57 -> 200
A42: Pattern digitized & graded ($) | B42: =Inputs!$B$58 -> 250 | C42: =Inputs!$B$58 -> 250 | D42: =Inputs!$B$58 -> 250 | E42: =Inputs!$B$58 -> 250 | F42: =Inputs!$B$58 -> 250 | G42: =Inputs!$B$58 -> 250 | H42: =Inputs!$B$58 -> 250 | I42: =Inputs!$B$58 -> 250 | ... M42: =Inputs!$B$58 -> 250
A43: TOTAL ONE-TIME FEES PER STYLE ($) | B43: =B41+B42 -> 450 | C43: =C41+C42 -> 450 | D43: =D41+D42 -> 450 | E43: =E41+E42 -> 450 | F43: =F41+F42 -> 450 | G43: =G41+G42 -> 450 | H43: =H41+H42 -> 450 | I43: =I41+I42 -> 450 | ... M43: =M41+M42 -> 450

Sheet Bottoms
A1: SWEATPANTS & SWEAT SHORTS COST PER UNIT
A2: Each column is one build. Pick a Style and Wash from the dropdowns (blue cells) — everything below is a formula pulling from the Inputs tab. Leave Wash blank for no wash. Green = pulled from Inputs, black = calculated.
A4: Style | B4: Sweatpants | C4: Sweatpants | D4: Sweatpants | E4: Sweat Shorts (Jorts Baggy Cut) | F4: Sweat Shorts (Jorts Baggy Cut) | G4: Sweat Shorts (Jorts Baggy Cut)
A5: Wash | B5: PP Spray (Potassium) | C5: Stone Wash | D5: Basic Wash / Dye | E5: PP Spray (Potassium) | F5: Stone Wash | G5: Basic Wash / Dye
A6: BODY FABRIC
A7: Body fabric | B7: =IF(INDEX(Inputs!$C$22:$C$37,MATCH(B$4,Inputs!$A$22:$A$37,0))="","",INDEX(Inputs!$C$22:$C$37,MATCH(B$4,Inputs!$A$22:$A$37,0))) -> 20oz Gabardine French Terry | C7: =IF(INDEX(Inputs!$C$22:$C$37,MATCH(C$4,Inputs!$A$22:$A$37,0))="","",INDEX(Inputs!$C$22:$C$37,MATCH(C$4,Inputs!$A$22:$A$37,0))) -> 20oz Gabardine French Terry | D7: =IF(INDEX(Inputs!$C$22:$C$37,MATCH(D$4,Inputs!$A$22:$A$37,0))="","",INDEX(Inputs!$C$22:$C$37,MATCH(D$4,Inputs!$A$22:$A$37,0))) -> 20oz Gabardine French Terry | E7: =IF(INDEX(Inputs!$C$22:$C$37,MATCH(E$4,Inputs!$A$22:$A$37,0))="","",INDEX(Inputs!$C$22:$C$37,MATCH(E$4,Inputs!$A$22:$A$37,0))) -> 20oz Gabardine French Terry | F7: =IF(INDEX(Inputs!$C$22:$C$37,MATCH(F$4,Inputs!$A$22:$A$37,0))="","",INDEX(Inputs!$C$22:$C$37,MATCH(F$4,Inputs!$A$22:$A$37,0))) -> 20oz Gabardine French Terry | G7: =IF(INDEX(Inputs!$C$22:$C$37,MATCH(G$4,Inputs!$A$22:$A$37,0))="","",INDEX(Inputs!$C$22:$C$37,MATCH(G$4,Inputs!$A$22:$A$37,0))) -> 20oz Gabardine French Terry
A8: Body yield (yd) | B8: =INDEX(Inputs!$D$22:$D$37,MATCH(B$4,Inputs!$A$22:$A$37,0)) -> 2.08 | C8: =INDEX(Inputs!$D$22:$D$37,MATCH(C$4,Inputs!$A$22:$A$37,0)) -> 2.08 | D8: =INDEX(Inputs!$D$22:$D$37,MATCH(D$4,Inputs!$A$22:$A$37,0)) -> 2.08 | E8: =INDEX(Inputs!$D$22:$D$37,MATCH(E$4,Inputs!$A$22:$A$37,0)) -> 1.45 | F8: =INDEX(Inputs!$D$22:$D$37,MATCH(F$4,Inputs!$A$22:$A$37,0)) -> 1.45 | G8: =INDEX(Inputs!$D$22:$D$37,MATCH(G$4,Inputs!$A$22:$A$37,0)) -> 1.45
A9: Body fabric price ($/yd) | B9: =IF(B7="",0,INDEX(Inputs!$B$6:$B$13,MATCH(B7,Inputs!$A$6:$A$13,0))) -> 8.57 | C9: =IF(C7="",0,INDEX(Inputs!$B$6:$B$13,MATCH(C7,Inputs!$A$6:$A$13,0))) -> 8.57 | D9: =IF(D7="",0,INDEX(Inputs!$B$6:$B$13,MATCH(D7,Inputs!$A$6:$A$13,0))) -> 8.57 | E9: =IF(E7="",0,INDEX(Inputs!$B$6:$B$13,MATCH(E7,Inputs!$A$6:$A$13,0))) -> 8.57 | F9: =IF(F7="",0,INDEX(Inputs!$B$6:$B$13,MATCH(F7,Inputs!$A$6:$A$13,0))) -> 8.57 | G9: =IF(G7="",0,INDEX(Inputs!$B$6:$B$13,MATCH(G7,Inputs!$A$6:$A$13,0))) -> 8.57
A10: Body fabric cost ($) | B10: =B8*B9 -> 17.8256 | C10: =C8*C9 -> 17.8256 | D10: =D8*D9 -> 17.8256 | E10: =E8*E9 -> 12.4265 | F10: =F8*F9 -> 12.4265 | G10: =G8*G9 -> 12.4265
A11: RIB
A12: Rib fabric | B12: =IF(INDEX(Inputs!$E$22:$E$37,MATCH(B$4,Inputs!$A$22:$A$37,0))="","",INDEX(Inputs!$E$22:$E$37,MATCH(B$4,Inputs!$A$22:$A$37,0))) | C12: =IF(INDEX(Inputs!$E$22:$E$37,MATCH(C$4,Inputs!$A$22:$A$37,0))="","",INDEX(Inputs!$E$22:$E$37,MATCH(C$4,Inputs!$A$22:$A$37,0))) | D12: =IF(INDEX(Inputs!$E$22:$E$37,MATCH(D$4,Inputs!$A$22:$A$37,0))="","",INDEX(Inputs!$E$22:$E$37,MATCH(D$4,Inputs!$A$22:$A$37,0))) | E12: =IF(INDEX(Inputs!$E$22:$E$37,MATCH(E$4,Inputs!$A$22:$A$37,0))="","",INDEX(Inputs!$E$22:$E$37,MATCH(E$4,Inputs!$A$22:$A$37,0))) | F12: =IF(INDEX(Inputs!$E$22:$E$37,MATCH(F$4,Inputs!$A$22:$A$37,0))="","",INDEX(Inputs!$E$22:$E$37,MATCH(F$4,Inputs!$A$22:$A$37,0))) | G12: =IF(INDEX(Inputs!$E$22:$E$37,MATCH(G$4,Inputs!$A$22:$A$37,0))="","",INDEX(Inputs!$E$22:$E$37,MATCH(G$4,Inputs!$A$22:$A$37,0)))
A13: Rib yield (yd) | B13: =INDEX(Inputs!$F$22:$F$37,MATCH(B$4,Inputs!$A$22:$A$37,0)) -> 0 | C13: =INDEX(Inputs!$F$22:$F$37,MATCH(C$4,Inputs!$A$22:$A$37,0)) -> 0 | D13: =INDEX(Inputs!$F$22:$F$37,MATCH(D$4,Inputs!$A$22:$A$37,0)) -> 0 | E13: =INDEX(Inputs!$F$22:$F$37,MATCH(E$4,Inputs!$A$22:$A$37,0)) -> 0 | F13: =INDEX(Inputs!$F$22:$F$37,MATCH(F$4,Inputs!$A$22:$A$37,0)) -> 0 | G13: =INDEX(Inputs!$F$22:$F$37,MATCH(G$4,Inputs!$A$22:$A$37,0)) -> 0
A14: Rib price ($/yd) | B14: =IF(B12="",0,INDEX(Inputs!$B$6:$B$13,MATCH(B12,Inputs!$A$6:$A$13,0))) -> 0 | C14: =IF(C12="",0,INDEX(Inputs!$B$6:$B$13,MATCH(C12,Inputs!$A$6:$A$13,0))) -> 0 | D14: =IF(D12="",0,INDEX(Inputs!$B$6:$B$13,MATCH(D12,Inputs!$A$6:$A$13,0))) -> 0 | E14: =IF(E12="",0,INDEX(Inputs!$B$6:$B$13,MATCH(E12,Inputs!$A$6:$A$13,0))) -> 0 | F14: =IF(F12="",0,INDEX(Inputs!$B$6:$B$13,MATCH(F12,Inputs!$A$6:$A$13,0))) -> 0 | G14: =IF(G12="",0,INDEX(Inputs!$B$6:$B$13,MATCH(G12,Inputs!$A$6:$A$13,0))) -> 0
A15: Rib cost ($) | B15: =B13*B14 -> 0 | C15: =C13*C14 -> 0 | D15: =D13*D14 -> 0 | E15: =E13*E14 -> 0 | F15: =F13*F14 -> 0 | G15: =G13*G14 -> 0
A16: DRAWSTRING & ELASTIC
A17: Drawstring (yd) | B17: =INDEX(Inputs!$G$22:$G$37,MATCH(B$4,Inputs!$A$22:$A$37,0)) -> 2.25 | C17: =INDEX(Inputs!$G$22:$G$37,MATCH(C$4,Inputs!$A$22:$A$37,0)) -> 2.25 | D17: =INDEX(Inputs!$G$22:$G$37,MATCH(D$4,Inputs!$A$22:$A$37,0)) -> 2.25 | E17: =INDEX(Inputs!$G$22:$G$37,MATCH(E$4,Inputs!$A$22:$A$37,0)) -> 2.25 | F17: =INDEX(Inputs!$G$22:$G$37,MATCH(F$4,Inputs!$A$22:$A$37,0)) -> 2.25 | G17: =INDEX(Inputs!$G$22:$G$37,MATCH(G$4,Inputs!$A$22:$A$37,0)) -> 2.25
A18: Drawstring price ($/yd) | B18: =Inputs!$B$17 -> 0.55 | C18: =Inputs!$B$17 -> 0.55 | D18: =Inputs!$B$17 -> 0.55 | E18: =Inputs!$B$17 -> 0.55 | F18: =Inputs!$B$17 -> 0.55 | G18: =Inputs!$B$17 -> 0.55
A19: Drawstring cost ($) | B19: =B17*B18 -> 1.2375 | C19: =C17*C18 -> 1.2375 | D19: =D17*D18 -> 1.2375 | E19: =E17*E18 -> 1.2375 | F19: =F17*F18 -> 1.2375 | G19: =G17*G18 -> 1.2375
A20: Elastic (yd) | B20: =INDEX(Inputs!$H$22:$H$37,MATCH(B$4,Inputs!$A$22:$A$37,0)) -> 1.5 | C20: =INDEX(Inputs!$H$22:$H$37,MATCH(C$4,Inputs!$A$22:$A$37,0)) -> 1.5 | D20: =INDEX(Inputs!$H$22:$H$37,MATCH(D$4,Inputs!$A$22:$A$37,0)) -> 1.5 | E20: =INDEX(Inputs!$H$22:$H$37,MATCH(E$4,Inputs!$A$22:$A$37,0)) -> 1.5 | F20: =INDEX(Inputs!$H$22:$H$37,MATCH(F$4,Inputs!$A$22:$A$37,0)) -> 1.5 | G20: =INDEX(Inputs!$H$22:$H$37,MATCH(G$4,Inputs!$A$22:$A$37,0)) -> 1.5
A21: Elastic price ($/yd) | B21: =Inputs!$B$18 -> 1 | C21: =Inputs!$B$18 -> 1 | D21: =Inputs!$B$18 -> 1 | E21: =Inputs!$B$18 -> 1 | F21: =Inputs!$B$18 -> 1 | G21: =Inputs!$B$18 -> 1
A22: Elastic cost ($) | B22: =B20*B21 -> 1.5 | C22: =C20*C21 -> 1.5 | D22: =D20*D21 -> 1.5 | E22: =E20*E21 -> 1.5 | F22: =F20*F21 -> 1.5 | G22: =G20*G21 -> 1.5
A23: WASH, LABOR, TRIMS & PACKAGING
A24: Wash cost ($) | B24: =IF(B5="",0,INDEX(Inputs!$B$43:$E$48,MATCH(B5,Inputs!$A$43:$A$48,0),MATCH(INDEX(Inputs!$B$22:$B$37,MATCH(B$4,Inputs!$A$22:$A$37,0)),Inputs!$B$42:$E$42,0))) -> 18 | C24: =IF(C5="",0,INDEX(Inputs!$B$43:$E$48,MATCH(C5,Inputs!$A$43:$A$48,0),MATCH(INDEX(Inputs!$B$22:$B$37,MATCH(C$4,Inputs!$A$22:$A$37,0)),Inputs!$B$42:$E$42,0))) -> 11 | D24: =IF(D5="",0,INDEX(Inputs!$B$43:$E$48,MATCH(D5,Inputs!$A$43:$A$48,0),MATCH(INDEX(Inputs!$B$22:$B$37,MATCH(D$4,Inputs!$A$22:$A$37,0)),Inputs!$B$42:$E$42,0))) -> 3.75 | E24: =IF(E5="",0,INDEX(Inputs!$B$43:$E$48,MATCH(E5,Inputs!$A$43:$A$48,0),MATCH(INDEX(Inputs!$B$22:$B$37,MATCH(E$4,Inputs!$A$22:$A$37,0)),Inputs!$B$42:$E$42,0))) -> 18 | F24: =IF(F5="",0,INDEX(Inputs!$B$43:$E$48,MATCH(F5,Inputs!$A$43:$A$48,0),MATCH(INDEX(Inputs!$B$22:$B$37,MATCH(F$4,Inputs!$A$22:$A$37,0)),Inputs!$B$42:$E$42,0))) -> 11 | G24: =IF(G5="",0,INDEX(Inputs!$B$43:$E$48,MATCH(G5,Inputs!$A$43:$A$48,0),MATCH(INDEX(Inputs!$B$22:$B$37,MATCH(G$4,Inputs!$A$22:$A$37,0)),Inputs!$B$42:$E$42,0))) -> 3.75
A25: Distress grinding ($) | B25: =INDEX(Inputs!$K$22:$K$37,MATCH(B$4,Inputs!$A$22:$A$37,0)) -> 2.5 | C25: =INDEX(Inputs!$K$22:$K$37,MATCH(C$4,Inputs!$A$22:$A$37,0)) -> 2.5 | D25: =INDEX(Inputs!$K$22:$K$37,MATCH(D$4,Inputs!$A$22:$A$37,0)) -> 2.5 | E25: =INDEX(Inputs!$K$22:$K$37,MATCH(E$4,Inputs!$A$22:$A$37,0)) -> 2.5 | F25: =INDEX(Inputs!$K$22:$K$37,MATCH(F$4,Inputs!$A$22:$A$37,0)) -> 2.5 | G25: =INDEX(Inputs!$K$22:$K$37,MATCH(G$4,Inputs!$A$22:$A$37,0)) -> 2.5
A26: Cutting ($) | B26: =INDEX(Inputs!$J$22:$J$37,MATCH(B$4,Inputs!$A$22:$A$37,0)) -> 1 | C26: =INDEX(Inputs!$J$22:$J$37,MATCH(C$4,Inputs!$A$22:$A$37,0)) -> 1 | D26: =INDEX(Inputs!$J$22:$J$37,MATCH(D$4,Inputs!$A$22:$A$37,0)) -> 1 | E26: =INDEX(Inputs!$J$22:$J$37,MATCH(E$4,Inputs!$A$22:$A$37,0)) -> 1 | F26: =INDEX(Inputs!$J$22:$J$37,MATCH(F$4,Inputs!$A$22:$A$37,0)) -> 1 | G26: =INDEX(Inputs!$J$22:$J$37,MATCH(G$4,Inputs!$A$22:$A$37,0)) -> 1
A27: Sewing ($) | B27: =INDEX(Inputs!$I$22:$I$37,MATCH(B$4,Inputs!$A$22:$A$37,0)) -> 18 | C27: =INDEX(Inputs!$I$22:$I$37,MATCH(C$4,Inputs!$A$22:$A$37,0)) -> 18 | D27: =INDEX(Inputs!$I$22:$I$37,MATCH(D$4,Inputs!$A$22:$A$37,0)) -> 18 | E27: =INDEX(Inputs!$I$22:$I$37,MATCH(E$4,Inputs!$A$22:$A$37,0)) -> 16 | F27: =INDEX(Inputs!$I$22:$I$37,MATCH(F$4,Inputs!$A$22:$A$37,0)) -> 16 | G27: =INDEX(Inputs!$I$22:$I$37,MATCH(G$4,Inputs!$A$22:$A$37,0)) -> 16
A28: Trims / other ($) | B28: =INDEX(Inputs!$M$22:$M$37,MATCH(B$4,Inputs!$A$22:$A$37,0)) -> 0 | C28: =INDEX(Inputs!$M$22:$M$37,MATCH(C$4,Inputs!$A$22:$A$37,0)) -> 0 | D28: =INDEX(Inputs!$M$22:$M$37,MATCH(D$4,Inputs!$A$22:$A$37,0)) -> 0 | E28: =INDEX(Inputs!$M$22:$M$37,MATCH(E$4,Inputs!$A$22:$A$37,0)) -> 0 | F28: =INDEX(Inputs!$M$22:$M$37,MATCH(F$4,Inputs!$A$22:$A$37,0)) -> 0 | G28: =INDEX(Inputs!$M$22:$M$37,MATCH(G$4,Inputs!$A$22:$A$37,0)) -> 0
A29: Packaging ($) | B29: =INDEX(Inputs!$L$22:$L$37,MATCH(B$4,Inputs!$A$22:$A$37,0)) -> 3.5 | C29: =INDEX(Inputs!$L$22:$L$37,MATCH(C$4,Inputs!$A$22:$A$37,0)) -> 3.5 | D29: =INDEX(Inputs!$L$22:$L$37,MATCH(D$4,Inputs!$A$22:$A$37,0)) -> 3.5 | E29: =INDEX(Inputs!$L$22:$L$37,MATCH(E$4,Inputs!$A$22:$A$37,0)) -> 3.5 | F29: =INDEX(Inputs!$L$22:$L$37,MATCH(F$4,Inputs!$A$22:$A$37,0)) -> 3.5 | G29: =INDEX(Inputs!$L$22:$L$37,MATCH(G$4,Inputs!$A$22:$A$37,0)) -> 3.5
A31: TOTAL COST PER UNIT ($) | B31: =B10+B15+B19+B22+B24+B25+B26+B27+B28+B29 -> 63.5631 | C31: =C10+C15+C19+C22+C24+C25+C26+C27+C28+C29 -> 56.5631 | D31: =D10+D15+D19+D22+D24+D25+D26+D27+D28+D29 -> 49.3131 | E31: =E10+E15+E19+E22+E24+E25+E26+E27+E28+E29 -> 56.164 | F31: =F10+F15+F19+F22+F24+F25+F26+F27+F28+F29 -> 49.164 | G31: =G10+G15+G19+G22+G24+G25+G26+G27+G28+G29 -> 41.914
A32: Status | B32: =IF(B7="","NO FABRIC SET — total excludes fabric",IF(B8=0,"MISSING YIELD — fabric not in total",IF(B9=0,"MISSING FABRIC PRICE — fabric not in total",IF(AND(B12<>"",B13=0),"MISSING RIB YIELD — rib not in total","Complete")))) -> Complete | C32: =IF(C7="","NO FABRIC SET — total excludes fabric",IF(C8=0,"MISSING YIELD — fabric not in total",IF(C9=0,"MISSING FABRIC PRICE — fabric not in total",IF(AND(C12<>"",C13=0),"MISSING RIB YIELD — rib not in total","Complete")))) -> Complete | D32: =IF(D7="","NO FABRIC SET — total excludes fabric",IF(D8=0,"MISSING YIELD — fabric not in total",IF(D9=0,"MISSING FABRIC PRICE — fabric not in total",IF(AND(D12<>"",D13=0),"MISSING RIB YIELD — rib not in total","Complete")))) -> Complete | E32: =IF(E7="","NO FABRIC SET — total excludes fabric",IF(E8=0,"MISSING YIELD — fabric not in total",IF(E9=0,"MISSING FABRIC PRICE — fabric not in total",IF(AND(E12<>"",E13=0),"MISSING RIB YIELD — rib not in total","Complete")))) -> Complete | F32: =IF(F7="","NO FABRIC SET — total excludes fabric",IF(F8=0,"MISSING YIELD — fabric not in total",IF(F9=0,"MISSING FABRIC PRICE — fabric not in total",IF(AND(F12<>"",F13=0),"MISSING RIB YIELD — rib not in total","Complete")))) -> Complete | G32: =IF(G7="","NO FABRIC SET — total excludes fabric",IF(G8=0,"MISSING YIELD — fabric not in total",IF(G9=0,"MISSING FABRIC PRICE — fabric not in total",IF(AND(G12<>"",G13=0),"MISSING RIB YIELD — rib not in total","Complete")))) -> Complete
A33: PRICING
A34: FSF markup % | B34: =Inputs!$B$52 -> 0.2 | C34: =Inputs!$B$52 -> 0.2 | D34: =Inputs!$B$52 -> 0.2 | E34: =Inputs!$B$52 -> 0.2 | F34: =Inputs!$B$52 -> 0.2 | G34: =Inputs!$B$52 -> 0.2
A35: FSF markup ($) | B35: =B31*B34 -> 12.71262 | C35: =C31*C34 -> 11.31262 | D35: =D31*D34 -> 9.86262 | E35: =E31*E34 -> 11.2328 | F35: =F31*F34 -> 9.8328 | G35: =G31*G34 -> 8.3828
A36: TOTAL COST INCL. FSF MARKUP ($) | B36: =B31+B35 -> 76.27572 | C36: =C31+C35 -> 67.87572 | D36: =D31+D35 -> 59.17572 | E36: =E31+E35 -> 67.3968 | F36: =F31+F35 -> 58.9968 | G36: =G31+G35 -> 50.2968
A37: Selling price multiple | B37: =Inputs!$B$53 -> 2.5 | C37: =Inputs!$B$53 -> 2.5 | D37: =Inputs!$B$53 -> 2.5 | E37: =Inputs!$B$53 -> 2.5 | F37: =Inputs!$B$53 -> 2.5 | G37: =Inputs!$B$53 -> 2.5
A38: SELLING PRICE PER UNIT ($) | B38: =B36*B37 -> 190.6893 | C38: =C36*C37 -> 169.6893 | D38: =D36*D37 -> 147.9393 | E38: =E36*E37 -> 168.492 | F38: =F36*F37 -> 147.492 | G38: =G36*G37 -> 125.742
A40: ONE-TIME FEES — charged once per style, not per garment or per wash; not in unit cost or selling price
A41: Pattern fee ($) | B41: =Inputs!$B$57 -> 200 | C41: =Inputs!$B$57 -> 200 | D41: =Inputs!$B$57 -> 200 | E41: =Inputs!$B$57 -> 200 | F41: =Inputs!$B$57 -> 200 | G41: =Inputs!$B$57 -> 200
A42: Pattern digitized & graded ($) | B42: =Inputs!$B$58 -> 250 | C42: =Inputs!$B$58 -> 250 | D42: =Inputs!$B$58 -> 250 | E42: =Inputs!$B$58 -> 250 | F42: =Inputs!$B$58 -> 250 | G42: =Inputs!$B$58 -> 250
A43: TOTAL ONE-TIME FEES PER STYLE ($) | B43: =B41+B42 -> 450 | C43: =C41+C42 -> 450 | D43: =D41+D42 -> 450 | E43: =E41+E42 -> 450 | F43: =F41+F42 -> 450 | G43: =G41+G42 -> 450

Sheet Tees
A1: TEES, THERMAL & TANK TOP COST PER UNIT
A2: Each column is one build. Pick a Style and Wash from the dropdowns (blue cells) — everything below is a formula pulling from the Inputs tab. Leave Wash blank for no wash. Green = pulled from Inputs, black = calculated.
A4: Style | B4: Short Sleeve Jersey Tee | C4: Short Sleeve Jersey Tee | D4: Short Sleeve Jersey Tee | E4: Long Sleeve Jersey Tee | F4: Long Sleeve Jersey Tee | G4: Long Sleeve Jersey Tee | H4: Thermal Long Sleeve | I4: Thermal Long Sleeve | J4: Thermal Long Sleeve | K4: Tank Top
A5: Wash | B5: PP Spray (Potassium) | C5: Stone Wash | D5: Basic Wash / Dye | E5: PP Spray (Potassium) | F5: Stone Wash | G5: Basic Wash / Dye | H5: PP Spray (Potassium) | I5: Stone Wash | J5: Basic Wash / Dye
A6: BODY FABRIC
A7: Body fabric | B7: =IF(INDEX(Inputs!$C$22:$C$37,MATCH(B$4,Inputs!$A$22:$A$37,0))="","",INDEX(Inputs!$C$22:$C$37,MATCH(B$4,Inputs!$A$22:$A$37,0))) -> Jersey | C7: =IF(INDEX(Inputs!$C$22:$C$37,MATCH(C$4,Inputs!$A$22:$A$37,0))="","",INDEX(Inputs!$C$22:$C$37,MATCH(C$4,Inputs!$A$22:$A$37,0))) -> Jersey | D7: =IF(INDEX(Inputs!$C$22:$C$37,MATCH(D$4,Inputs!$A$22:$A$37,0))="","",INDEX(Inputs!$C$22:$C$37,MATCH(D$4,Inputs!$A$22:$A$37,0))) -> Jersey | E7: =IF(INDEX(Inputs!$C$22:$C$37,MATCH(E$4,Inputs!$A$22:$A$37,0))="","",INDEX(Inputs!$C$22:$C$37,MATCH(E$4,Inputs!$A$22:$A$37,0))) -> Jersey | F7: =IF(INDEX(Inputs!$C$22:$C$37,MATCH(F$4,Inputs!$A$22:$A$37,0))="","",INDEX(Inputs!$C$22:$C$37,MATCH(F$4,Inputs!$A$22:$A$37,0))) -> Jersey | G7: =IF(INDEX(Inputs!$C$22:$C$37,MATCH(G$4,Inputs!$A$22:$A$37,0))="","",INDEX(Inputs!$C$22:$C$37,MATCH(G$4,Inputs!$A$22:$A$37,0))) -> Jersey | H7: =IF(INDEX(Inputs!$C$22:$C$37,MATCH(H$4,Inputs!$A$22:$A$37,0))="","",INDEX(Inputs!$C$22:$C$37,MATCH(H$4,Inputs!$A$22:$A$37,0))) -> Thermal | I7: =IF(INDEX(Inputs!$C$22:$C$37,MATCH(I$4,Inputs!$A$22:$A$37,0))="","",INDEX(Inputs!$C$22:$C$37,MATCH(I$4,Inputs!$A$22:$A$37,0))) -> Thermal | ... K7: =IF(INDEX(Inputs!$C$22:$C$37,MATCH(K$4,Inputs!$A$22:$A$37,0))="","",INDEX(Inputs!$C$22:$C$37,MATCH(K$4,Inputs!$A$22:$A$37,0))) -> Rib Knit
A8: Body yield (yd) | B8: =INDEX(Inputs!$D$22:$D$37,MATCH(B$4,Inputs!$A$22:$A$37,0)) -> 1.08 | C8: =INDEX(Inputs!$D$22:$D$37,MATCH(C$4,Inputs!$A$22:$A$37,0)) -> 1.08 | D8: =INDEX(Inputs!$D$22:$D$37,MATCH(D$4,Inputs!$A$22:$A$37,0)) -> 1.08 | E8: =INDEX(Inputs!$D$22:$D$37,MATCH(E$4,Inputs!$A$22:$A$37,0)) -> 1.6 | F8: =INDEX(Inputs!$D$22:$D$37,MATCH(F$4,Inputs!$A$22:$A$37,0)) -> 1.6 | G8: =INDEX(Inputs!$D$22:$D$37,MATCH(G$4,Inputs!$A$22:$A$37,0)) -> 1.6 | H8: =INDEX(Inputs!$D$22:$D$37,MATCH(H$4,Inputs!$A$22:$A$37,0)) -> 1.6 | I8: =INDEX(Inputs!$D$22:$D$37,MATCH(I$4,Inputs!$A$22:$A$37,0)) -> 1.6 | ... K8: =INDEX(Inputs!$D$22:$D$37,MATCH(K$4,Inputs!$A$22:$A$37,0)) -> 0.75
A9: Body fabric price ($/yd) | B9: =IF(B7="",0,INDEX(Inputs!$B$6:$B$13,MATCH(B7,Inputs!$A$6:$A$13,0))) -> 3.95 | C9: =IF(C7="",0,INDEX(Inputs!$B$6:$B$13,MATCH(C7,Inputs!$A$6:$A$13,0))) -> 3.95 | D9: =IF(D7="",0,INDEX(Inputs!$B$6:$B$13,MATCH(D7,Inputs!$A$6:$A$13,0))) -> 3.95 | E9: =IF(E7="",0,INDEX(Inputs!$B$6:$B$13,MATCH(E7,Inputs!$A$6:$A$13,0))) -> 3.95 | F9: =IF(F7="",0,INDEX(Inputs!$B$6:$B$13,MATCH(F7,Inputs!$A$6:$A$13,0))) -> 3.95 | G9: =IF(G7="",0,INDEX(Inputs!$B$6:$B$13,MATCH(G7,Inputs!$A$6:$A$13,0))) -> 3.95 | H9: =IF(H7="",0,INDEX(Inputs!$B$6:$B$13,MATCH(H7,Inputs!$A$6:$A$13,0))) -> 4.95 | I9: =IF(I7="",0,INDEX(Inputs!$B$6:$B$13,MATCH(I7,Inputs!$A$6:$A$13,0))) -> 4.95 | ... K9: =IF(K7="",0,INDEX(Inputs!$B$6:$B$13,MATCH(K7,Inputs!$A$6:$A$13,0))) -> 6.95
A10: Body fabric cost ($) | B10: =B8*B9 -> 4.266 | C10: =C8*C9 -> 4.266 | D10: =D8*D9 -> 4.266 | E10: =E8*E9 -> 6.32 | F10: =F8*F9 -> 6.32 | G10: =G8*G9 -> 6.32 | H10: =H8*H9 -> 7.92 | I10: =I8*I9 -> 7.92 | ... K10: =K8*K9 -> 5.2125
A11: RIB
A12: Rib fabric | B12: =IF(INDEX(Inputs!$E$22:$E$37,MATCH(B$4,Inputs!$A$22:$A$37,0))="","",INDEX(Inputs!$E$22:$E$37,MATCH(B$4,Inputs!$A$22:$A$37,0))) -> Collar Rib (Tees) | C12: =IF(INDEX(Inputs!$E$22:$E$37,MATCH(C$4,Inputs!$A$22:$A$37,0))="","",INDEX(Inputs!$E$22:$E$37,MATCH(C$4,Inputs!$A$22:$A$37,0))) -> Collar Rib (Tees) | D12: =IF(INDEX(Inputs!$E$22:$E$37,MATCH(D$4,Inputs!$A$22:$A$37,0))="","",INDEX(Inputs!$E$22:$E$37,MATCH(D$4,Inputs!$A$22:$A$37,0))) -> Collar Rib (Tees) | E12: =IF(INDEX(Inputs!$E$22:$E$37,MATCH(E$4,Inputs!$A$22:$A$37,0))="","",INDEX(Inputs!$E$22:$E$37,MATCH(E$4,Inputs!$A$22:$A$37,0))) -> Collar Rib (Tees) | F12: =IF(INDEX(Inputs!$E$22:$E$37,MATCH(F$4,Inputs!$A$22:$A$37,0))="","",INDEX(Inputs!$E$22:$E$37,MATCH(F$4,Inputs!$A$22:$A$37,0))) -> Collar Rib (Tees) | G12: =IF(INDEX(Inputs!$E$22:$E$37,MATCH(G$4,Inputs!$A$22:$A$37,0))="","",INDEX(Inputs!$E$22:$E$37,MATCH(G$4,Inputs!$A$22:$A$37,0))) -> Collar Rib (Tees) | H12: =IF(INDEX(Inputs!$E$22:$E$37,MATCH(H$4,Inputs!$A$22:$A$37,0))="","",INDEX(Inputs!$E$22:$E$37,MATCH(H$4,Inputs!$A$22:$A$37,0))) -> Collar Rib (Tees) | I12: =IF(INDEX(Inputs!$E$22:$E$37,MATCH(I$4,Inputs!$A$22:$A$37,0))="","",INDEX(Inputs!$E$22:$E$37,MATCH(I$4,Inputs!$A$22:$A$37,0))) -> Collar Rib (Tees) | ... K12: =IF(INDEX(Inputs!$E$22:$E$37,MATCH(K$4,Inputs!$A$22:$A$37,0))="","",INDEX(Inputs!$E$22:$E$37,MATCH(K$4,Inputs!$A$22:$A$37,0)))
A13: Rib yield (yd) | B13: =INDEX(Inputs!$F$22:$F$37,MATCH(B$4,Inputs!$A$22:$A$37,0)) -> 0.25 | C13: =INDEX(Inputs!$F$22:$F$37,MATCH(C$4,Inputs!$A$22:$A$37,0)) -> 0.25 | D13: =INDEX(Inputs!$F$22:$F$37,MATCH(D$4,Inputs!$A$22:$A$37,0)) -> 0.25 | E13: =INDEX(Inputs!$F$22:$F$37,MATCH(E$4,Inputs!$A$22:$A$37,0)) -> 0.25 | F13: =INDEX(Inputs!$F$22:$F$37,MATCH(F$4,Inputs!$A$22:$A$37,0)) -> 0.25 | G13: =INDEX(Inputs!$F$22:$F$37,MATCH(G$4,Inputs!$A$22:$A$37,0)) -> 0.25 | H13: =INDEX(Inputs!$F$22:$F$37,MATCH(H$4,Inputs!$A$22:$A$37,0)) -> 0.25 | I13: =INDEX(Inputs!$F$22:$F$37,MATCH(I$4,Inputs!$A$22:$A$37,0)) -> 0.25 | ... K13: =INDEX(Inputs!$F$22:$F$37,MATCH(K$4,Inputs!$A$22:$A$37,0)) -> 0
A14: Rib price ($/yd) | B14: =IF(B12="",0,INDEX(Inputs!$B$6:$B$13,MATCH(B12,Inputs!$A$6:$A$13,0))) -> 3.95 | C14: =IF(C12="",0,INDEX(Inputs!$B$6:$B$13,MATCH(C12,Inputs!$A$6:$A$13,0))) -> 3.95 | D14: =IF(D12="",0,INDEX(Inputs!$B$6:$B$13,MATCH(D12,Inputs!$A$6:$A$13,0))) -> 3.95 | E14: =IF(E12="",0,INDEX(Inputs!$B$6:$B$13,MATCH(E12,Inputs!$A$6:$A$13,0))) -> 3.95 | F14: =IF(F12="",0,INDEX(Inputs!$B$6:$B$13,MATCH(F12,Inputs!$A$6:$A$13,0))) -> 3.95 | G14: =IF(G12="",0,INDEX(Inputs!$B$6:$B$13,MATCH(G12,Inputs!$A$6:$A$13,0))) -> 3.95 | H14: =IF(H12="",0,INDEX(Inputs!$B$6:$B$13,MATCH(H12,Inputs!$A$6:$A$13,0))) -> 3.95 | I14: =IF(I12="",0,INDEX(Inputs!$B$6:$B$13,MATCH(I12,Inputs!$A$6:$A$13,0))) -> 3.95 | ... K14: =IF(K12="",0,INDEX(Inputs!$B$6:$B$13,MATCH(K12,Inputs!$A$6:$A$13,0))) -> 0
A15: Rib cost ($) | B15: =B13*B14 -> 0.9875 | C15: =C13*C14 -> 0.9875 | D15: =D13*D14 -> 0.9875 | E15: =E13*E14 -> 0.9875 | F15: =F13*F14 -> 0.9875 | G15: =G13*G14 -> 0.9875 | H15: =H13*H14 -> 0.9875 | I15: =I13*I14 -> 0.9875 | ... K15: =K13*K14 -> 0
A16: DRAWSTRING & ELASTIC
A17: Drawstring (yd) | B17: =INDEX(Inputs!$G$22:$G$37,MATCH(B$4,Inputs!$A$22:$A$37,0)) -> 0 | C17: =INDEX(Inputs!$G$22:$G$37,MATCH(C$4,Inputs!$A$22:$A$37,0)) -> 0 | D17: =INDEX(Inputs!$G$22:$G$37,MATCH(D$4,Inputs!$A$22:$A$37,0)) -> 0 | E17: =INDEX(Inputs!$G$22:$G$37,MATCH(E$4,Inputs!$A$22:$A$37,0)) -> 0 | F17: =INDEX(Inputs!$G$22:$G$37,MATCH(F$4,Inputs!$A$22:$A$37,0)) -> 0 | G17: =INDEX(Inputs!$G$22:$G$37,MATCH(G$4,Inputs!$A$22:$A$37,0)) -> 0 | H17: =INDEX(Inputs!$G$22:$G$37,MATCH(H$4,Inputs!$A$22:$A$37,0)) -> 0 | I17: =INDEX(Inputs!$G$22:$G$37,MATCH(I$4,Inputs!$A$22:$A$37,0)) -> 0 | ... K17: =INDEX(Inputs!$G$22:$G$37,MATCH(K$4,Inputs!$A$22:$A$37,0)) -> 0
A18: Drawstring price ($/yd) | B18: =Inputs!$B$17 -> 0.55 | C18: =Inputs!$B$17 -> 0.55 | D18: =Inputs!$B$17 -> 0.55 | E18: =Inputs!$B$17 -> 0.55 | F18: =Inputs!$B$17 -> 0.55 | G18: =Inputs!$B$17 -> 0.55 | H18: =Inputs!$B$17 -> 0.55 | I18: =Inputs!$B$17 -> 0.55 | ... K18: =Inputs!$B$17 -> 0.55
A19: Drawstring cost ($) | B19: =B17*B18 -> 0 | C19: =C17*C18 -> 0 | D19: =D17*D18 -> 0 | E19: =E17*E18 -> 0 | F19: =F17*F18 -> 0 | G19: =G17*G18 -> 0 | H19: =H17*H18 -> 0 | I19: =I17*I18 -> 0 | ... K19: =K17*K18 -> 0
A20: Elastic (yd) | B20: =INDEX(Inputs!$H$22:$H$37,MATCH(B$4,Inputs!$A$22:$A$37,0)) -> 0 | C20: =INDEX(Inputs!$H$22:$H$37,MATCH(C$4,Inputs!$A$22:$A$37,0)) -> 0 | D20: =INDEX(Inputs!$H$22:$H$37,MATCH(D$4,Inputs!$A$22:$A$37,0)) -> 0 | E20: =INDEX(Inputs!$H$22:$H$37,MATCH(E$4,Inputs!$A$22:$A$37,0)) -> 0 | F20: =INDEX(Inputs!$H$22:$H$37,MATCH(F$4,Inputs!$A$22:$A$37,0)) -> 0 | G20: =INDEX(Inputs!$H$22:$H$37,MATCH(G$4,Inputs!$A$22:$A$37,0)) -> 0 | H20: =INDEX(Inputs!$H$22:$H$37,MATCH(H$4,Inputs!$A$22:$A$37,0)) -> 0 | I20: =INDEX(Inputs!$H$22:$H$37,MATCH(I$4,Inputs!$A$22:$A$37,0)) -> 0 | ... K20: =INDEX(Inputs!$H$22:$H$37,MATCH(K$4,Inputs!$A$22:$A$37,0)) -> 0
A21: Elastic price ($/yd) | B21: =Inputs!$B$18 -> 1 | C21: =Inputs!$B$18 -> 1 | D21: =Inputs!$B$18 -> 1 | E21: =Inputs!$B$18 -> 1 | F21: =Inputs!$B$18 -> 1 | G21: =Inputs!$B$18 -> 1 | H21: =Inputs!$B$18 -> 1 | I21: =Inputs!$B$18 -> 1 | ... K21: =Inputs!$B$18 -> 1
A22: Elastic cost ($) | B22: =B20*B21 -> 0 | C22: =C20*C21 -> 0 | D22: =D20*D21 -> 0 | E22: =E20*E21 -> 0 | F22: =F20*F21 -> 0 | G22: =G20*G21 -> 0 | H22: =H20*H21 -> 0 | I22: =I20*I21 -> 0 | ... K22: =K20*K21 -> 0
A23: WASH, LABOR, TRIMS & PACKAGING
A24: Wash cost ($) | B24: =IF(B5="",0,INDEX(Inputs!$B$43:$E$48,MATCH(B5,Inputs!$A$43:$A$48,0),MATCH(INDEX(Inputs!$B$22:$B$37,MATCH(B$4,Inputs!$A$22:$A$37,0)),Inputs!$B$42:$E$42,0))) -> 12 | C24: =IF(C5="",0,INDEX(Inputs!$B$43:$E$48,MATCH(C5,Inputs!$A$43:$A$48,0),MATCH(INDEX(Inputs!$B$22:$B$37,MATCH(C$4,Inputs!$A$22:$A$37,0)),Inputs!$B$42:$E$42,0))) -> 6 | D24: =IF(D5="",0,INDEX(Inputs!$B$43:$E$48,MATCH(D5,Inputs!$A$43:$A$48,0),MATCH(INDEX(Inputs!$B$22:$B$37,MATCH(D$4,Inputs!$A$22:$A$37,0)),Inputs!$B$42:$E$42,0))) -> 2.75 | E24: =IF(E5="",0,INDEX(Inputs!$B$43:$E$48,MATCH(E5,Inputs!$A$43:$A$48,0),MATCH(INDEX(Inputs!$B$22:$B$37,MATCH(E$4,Inputs!$A$22:$A$37,0)),Inputs!$B$42:$E$42,0))) -> 12 | F24: =IF(F5="",0,INDEX(Inputs!$B$43:$E$48,MATCH(F5,Inputs!$A$43:$A$48,0),MATCH(INDEX(Inputs!$B$22:$B$37,MATCH(F$4,Inputs!$A$22:$A$37,0)),Inputs!$B$42:$E$42,0))) -> 6 | G24: =IF(G5="",0,INDEX(Inputs!$B$43:$E$48,MATCH(G5,Inputs!$A$43:$A$48,0),MATCH(INDEX(Inputs!$B$22:$B$37,MATCH(G$4,Inputs!$A$22:$A$37,0)),Inputs!$B$42:$E$42,0))) -> 2.75 | H24: =IF(H5="",0,INDEX(Inputs!$B$43:$E$48,MATCH(H5,Inputs!$A$43:$A$48,0),MATCH(INDEX(Inputs!$B$22:$B$37,MATCH(H$4,Inputs!$A$22:$A$37,0)),Inputs!$B$42:$E$42,0))) -> 12 | I24: =IF(I5="",0,INDEX(Inputs!$B$43:$E$48,MATCH(I5,Inputs!$A$43:$A$48,0),MATCH(INDEX(Inputs!$B$22:$B$37,MATCH(I$4,Inputs!$A$22:$A$37,0)),Inputs!$B$42:$E$42,0))) -> 6 | ... K24: =IF(K5="",0,INDEX(Inputs!$B$43:$E$48,MATCH(K5,Inputs!$A$43:$A$48,0),MATCH(INDEX(Inputs!$B$22:$B$37,MATCH(K$4,Inputs!$A$22:$A$37,0)),Inputs!$B$42:$E$42,0))) -> 0
A25: Distress grinding ($) | B25: =INDEX(Inputs!$K$22:$K$37,MATCH(B$4,Inputs!$A$22:$A$37,0)) -> 0 | C25: =INDEX(Inputs!$K$22:$K$37,MATCH(C$4,Inputs!$A$22:$A$37,0)) -> 0 | D25: =INDEX(Inputs!$K$22:$K$37,MATCH(D$4,Inputs!$A$22:$A$37,0)) -> 0 | E25: =INDEX(Inputs!$K$22:$K$37,MATCH(E$4,Inputs!$A$22:$A$37,0)) -> 0 | F25: =INDEX(Inputs!$K$22:$K$37,MATCH(F$4,Inputs!$A$22:$A$37,0)) -> 0 | G25: =INDEX(Inputs!$K$22:$K$37,MATCH(G$4,Inputs!$A$22:$A$37,0)) -> 0 | H25: =INDEX(Inputs!$K$22:$K$37,MATCH(H$4,Inputs!$A$22:$A$37,0)) -> 0 | I25: =INDEX(Inputs!$K$22:$K$37,MATCH(I$4,Inputs!$A$22:$A$37,0)) -> 0 | ... K25: =INDEX(Inputs!$K$22:$K$37,MATCH(K$4,Inputs!$A$22:$A$37,0)) -> 0
A26: Cutting ($) | B26: =INDEX(Inputs!$J$22:$J$37,MATCH(B$4,Inputs!$A$22:$A$37,0)) -> 0.63 | C26: =INDEX(Inputs!$J$22:$J$37,MATCH(C$4,Inputs!$A$22:$A$37,0)) -> 0.63 | D26: =INDEX(Inputs!$J$22:$J$37,MATCH(D$4,Inputs!$A$22:$A$37,0)) -> 0.63 | E26: =INDEX(Inputs!$J$22:$J$37,MATCH(E$4,Inputs!$A$22:$A$37,0)) -> 1 | F26: =INDEX(Inputs!$J$22:$J$37,MATCH(F$4,Inputs!$A$22:$A$37,0)) -> 1 | G26: =INDEX(Inputs!$J$22:$J$37,MATCH(G$4,Inputs!$A$22:$A$37,0)) -> 1 | H26: =INDEX(Inputs!$J$22:$J$37,MATCH(H$4,Inputs!$A$22:$A$37,0)) -> 1 | I26: =INDEX(Inputs!$J$22:$J$37,MATCH(I$4,Inputs!$A$22:$A$37,0)) -> 1 | ... K26: =INDEX(Inputs!$J$22:$J$37,MATCH(K$4,Inputs!$A$22:$A$37,0)) -> 0.95
A27: Sewing ($) | B27: =INDEX(Inputs!$I$22:$I$37,MATCH(B$4,Inputs!$A$22:$A$37,0)) -> 10 | C27: =INDEX(Inputs!$I$22:$I$37,MATCH(C$4,Inputs!$A$22:$A$37,0)) -> 10 | D27: =INDEX(Inputs!$I$22:$I$37,MATCH(D$4,Inputs!$A$22:$A$37,0)) -> 10 | E27: =INDEX(Inputs!$I$22:$I$37,MATCH(E$4,Inputs!$A$22:$A$37,0)) -> 12 | F27: =INDEX(Inputs!$I$22:$I$37,MATCH(F$4,Inputs!$A$22:$A$37,0)) -> 12 | G27: =INDEX(Inputs!$I$22:$I$37,MATCH(G$4,Inputs!$A$22:$A$37,0)) -> 12 | H27: =INDEX(Inputs!$I$22:$I$37,MATCH(H$4,Inputs!$A$22:$A$37,0)) -> 12 | I27: =INDEX(Inputs!$I$22:$I$37,MATCH(I$4,Inputs!$A$22:$A$37,0)) -> 12 | ... K27: =INDEX(Inputs!$I$22:$I$37,MATCH(K$4,Inputs!$A$22:$A$37,0)) -> 8
A28: Trims / other ($) | B28: =INDEX(Inputs!$M$22:$M$37,MATCH(B$4,Inputs!$A$22:$A$37,0)) -> 0 | C28: =INDEX(Inputs!$M$22:$M$37,MATCH(C$4,Inputs!$A$22:$A$37,0)) -> 0 | D28: =INDEX(Inputs!$M$22:$M$37,MATCH(D$4,Inputs!$A$22:$A$37,0)) -> 0 | E28: =INDEX(Inputs!$M$22:$M$37,MATCH(E$4,Inputs!$A$22:$A$37,0)) -> 0 | F28: =INDEX(Inputs!$M$22:$M$37,MATCH(F$4,Inputs!$A$22:$A$37,0)) -> 0 | G28: =INDEX(Inputs!$M$22:$M$37,MATCH(G$4,Inputs!$A$22:$A$37,0)) -> 0 | H28: =INDEX(Inputs!$M$22:$M$37,MATCH(H$4,Inputs!$A$22:$A$37,0)) -> 0 | I28: =INDEX(Inputs!$M$22:$M$37,MATCH(I$4,Inputs!$A$22:$A$37,0)) -> 0 | ... K28: =INDEX(Inputs!$M$22:$M$37,MATCH(K$4,Inputs!$A$22:$A$37,0)) -> 0
A29: Packaging ($) | B29: =INDEX(Inputs!$L$22:$L$37,MATCH(B$4,Inputs!$A$22:$A$37,0)) -> 3.5 | C29: =INDEX(Inputs!$L$22:$L$37,MATCH(C$4,Inputs!$A$22:$A$37,0)) -> 3.5 | D29: =INDEX(Inputs!$L$22:$L$37,MATCH(D$4,Inputs!$A$22:$A$37,0)) -> 3.5 | E29: =INDEX(Inputs!$L$22:$L$37,MATCH(E$4,Inputs!$A$22:$A$37,0)) -> 3.5 | F29: =INDEX(Inputs!$L$22:$L$37,MATCH(F$4,Inputs!$A$22:$A$37,0)) -> 3.5 | G29: =INDEX(Inputs!$L$22:$L$37,MATCH(G$4,Inputs!$A$22:$A$37,0)) -> 3.5 | H29: =INDEX(Inputs!$L$22:$L$37,MATCH(H$4,Inputs!$A$22:$A$37,0)) -> 3.5 | I29: =INDEX(Inputs!$L$22:$L$37,MATCH(I$4,Inputs!$A$22:$A$37,0)) -> 3.5 | ... K29: =INDEX(Inputs!$L$22:$L$37,MATCH(K$4,Inputs!$A$22:$A$37,0)) -> 3.5
A31: TOTAL COST PER UNIT ($) | B31: =B10+B15+B19+B22+B24+B25+B26+B27+B28+B29 -> 31.3835 | C31: =C10+C15+C19+C22+C24+C25+C26+C27+C28+C29 -> 25.3835 | D31: =D10+D15+D19+D22+D24+D25+D26+D27+D28+D29 -> 22.1335 | E31: =E10+E15+E19+E22+E24+E25+E26+E27+E28+E29 -> 35.8075 | F31: =F10+F15+F19+F22+F24+F25+F26+F27+F28+F29 -> 29.8075 | G31: =G10+G15+G19+G22+G24+G25+G26+G27+G28+G29 -> 26.5575 | H31: =H10+H15+H19+H22+H24+H25+H26+H27+H28+H29 -> 37.4075 | I31: =I10+I15+I19+I22+I24+I25+I26+I27+I28+I29 -> 31.4075 | ... K31: =K10+K15+K19+K22+K24+K25+K26+K27+K28+K29 -> 17.6625
A32: Status | B32: =IF(B7="","NO FABRIC SET — total excludes fabric",IF(B8=0,"MISSING YIELD — fabric not in total",IF(B9=0,"MISSING FABRIC PRICE — fabric not in total",IF(AND(B12<>"",B13=0),"MISSING RIB YIELD — rib not in total","Complete")))) -> Complete | C32: =IF(C7="","NO FABRIC SET — total excludes fabric",IF(C8=0,"MISSING YIELD — fabric not in total",IF(C9=0,"MISSING FABRIC PRICE — fabric not in total",IF(AND(C12<>"",C13=0),"MISSING RIB YIELD — rib not in total","Complete")))) -> Complete | D32: =IF(D7="","NO FABRIC SET — total excludes fabric",IF(D8=0,"MISSING YIELD — fabric not in total",IF(D9=0,"MISSING FABRIC PRICE — fabric not in total",IF(AND(D12<>"",D13=0),"MISSING RIB YIELD — rib not in total","Complete")))) -> Complete | E32: =IF(E7="","NO FABRIC SET — total excludes fabric",IF(E8=0,"MISSING YIELD — fabric not in total",IF(E9=0,"MISSING FABRIC PRICE — fabric not in total",IF(AND(E12<>"",E13=0),"MISSING RIB YIELD — rib not in total","Complete")))) -> Complete | F32: =IF(F7="","NO FABRIC SET — total excludes fabric",IF(F8=0,"MISSING YIELD — fabric not in total",IF(F9=0,"MISSING FABRIC PRICE — fabric not in total",IF(AND(F12<>"",F13=0),"MISSING RIB YIELD — rib not in total","Complete")))) -> Complete | G32: =IF(G7="","NO FABRIC SET — total excludes fabric",IF(G8=0,"MISSING YIELD — fabric not in total",IF(G9=0,"MISSING FABRIC PRICE — fabric not in total",IF(AND(G12<>"",G13=0),"MISSING RIB YIELD — rib not in total","Complete")))) -> Complete | H32: =IF(H7="","NO FABRIC SET — total excludes fabric",IF(H8=0,"MISSING YIELD — fabric not in total",IF(H9=0,"MISSING FABRIC PRICE — fabric not in total",IF(AND(H12<>"",H13=0),"MISSING RIB YIELD — rib not in total","Complete")))) -> Complete | I32: =IF(I7="","NO FABRIC SET — total excludes fabric",IF(I8=0,"MISSING YIELD — fabric not in total",IF(I9=0,"MISSING FABRIC PRICE — fabric not in total",IF(AND(I12<>"",I13=0),"MISSING RIB YIELD — rib not in total","Complete")))) -> Complete | ... K32: =IF(K7="","NO FABRIC SET — total excludes fabric",IF(K8=0,"MISSING YIELD — fabric not in total",IF(K9=0,"MISSING FABRIC PRICE — fabric not in total",IF(AND(K12<>"",K13=0),"MISSING RIB YIELD — rib not in total","Complete")))) -> Complete
A33: PRICING
A34: FSF markup % | B34: =Inputs!$B$52 -> 0.2 | C34: =Inputs!$B$52 -> 0.2 | D34: =Inputs!$B$52 -> 0.2 | E34: =Inputs!$B$52 -> 0.2 | F34: =Inputs!$B$52 -> 0.2 | G34: =Inputs!$B$52 -> 0.2 | H34: =Inputs!$B$52 -> 0.2 | I34: =Inputs!$B$52 -> 0.2 | ... K34: =Inputs!$B$52 -> 0.2
A35: FSF markup ($) | B35: =B31*B34 -> 6.2767 | C35: =C31*C34 -> 5.0767 | D35: =D31*D34 -> 4.4267 | E35: =E31*E34 -> 7.1615 | F35: =F31*F34 -> 5.9615 | G35: =G31*G34 -> 5.3115 | H35: =H31*H34 -> 7.4815 | I35: =I31*I34 -> 6.2815 | ... K35: =K31*K34 -> 3.5325
A36: TOTAL COST INCL. FSF MARKUP ($) | B36: =B31+B35 -> 37.6602 | C36: =C31+C35 -> 30.4602 | D36: =D31+D35 -> 26.5602 | E36: =E31+E35 -> 42.969 | F36: =F31+F35 -> 35.769 | G36: =G31+G35 -> 31.869 | H36: =H31+H35 -> 44.889 | I36: =I31+I35 -> 37.689 | ... K36: =K31+K35 -> 21.195
A37: Selling price multiple | B37: =Inputs!$B$53 -> 2.5 | C37: =Inputs!$B$53 -> 2.5 | D37: =Inputs!$B$53 -> 2.5 | E37: =Inputs!$B$53 -> 2.5 | F37: =Inputs!$B$53 -> 2.5 | G37: =Inputs!$B$53 -> 2.5 | H37: =Inputs!$B$53 -> 2.5 | I37: =Inputs!$B$53 -> 2.5 | ... K37: =Inputs!$B$53 -> 2.5
A38: SELLING PRICE PER UNIT ($) | B38: =B36*B37 -> 94.1505 | C38: =C36*C37 -> 76.1505 | D38: =D36*D37 -> 66.4005 | E38: =E36*E37 -> 107.4225 | F38: =F36*F37 -> 89.4225 | G38: =G36*G37 -> 79.6725 | H38: =H36*H37 -> 112.2225 | I38: =I36*I37 -> 94.2225 | ... K38: =K36*K37 -> 52.9875
A40: ONE-TIME FEES — charged once per style, not per garment or per wash; not in unit cost or selling price
A41: Pattern fee ($) | B41: =Inputs!$B$57 -> 200 | C41: =Inputs!$B$57 -> 200 | D41: =Inputs!$B$57 -> 200 | E41: =Inputs!$B$57 -> 200 | F41: =Inputs!$B$57 -> 200 | G41: =Inputs!$B$57 -> 200 | H41: =Inputs!$B$57 -> 200 | I41: =Inputs!$B$57 -> 200 | ... K41: =Inputs!$B$57 -> 200
A42: Pattern digitized & graded ($) | B42: =Inputs!$B$58 -> 250 | C42: =Inputs!$B$58 -> 250 | D42: =Inputs!$B$58 -> 250 | E42: =Inputs!$B$58 -> 250 | F42: =Inputs!$B$58 -> 250 | G42: =Inputs!$B$58 -> 250 | H42: =Inputs!$B$58 -> 250 | I42: =Inputs!$B$58 -> 250 | ... K42: =Inputs!$B$58 -> 250
A43: TOTAL ONE-TIME FEES PER STYLE ($) | B43: =B41+B42 -> 450 | C43: =C41+C42 -> 450 | D43: =D41+D42 -> 450 | E43: =E41+E42 -> 450 | F43: =F41+F42 -> 450 | G43: =G41+G42 -> 450 | H43: =H41+H42 -> 450 | I43: =I41+I42 -> 450 | ... K43: =K41+K42 -> 450

Sheet Track
A1: TRACK JACKET & TRACK PANTS COST PER UNIT
A2: Each column is one build. Pick a Style and Wash from the dropdowns (blue cells) — everything below is a formula pulling from the Inputs tab. Leave Wash blank for no wash. Green = pulled from Inputs, black = calculated.
A4: Style | B4: Track Jacket | C4: Track Pants
A5: Wash
A6: BODY FABRIC
A7: Body fabric | B7: =IF(INDEX(Inputs!$C$22:$C$37,MATCH(B$4,Inputs!$A$22:$A$37,0))="","",INDEX(Inputs!$C$22:$C$37,MATCH(B$4,Inputs!$A$22:$A$37,0))) -> Nylon | C7: =IF(INDEX(Inputs!$C$22:$C$37,MATCH(C$4,Inputs!$A$22:$A$37,0))="","",INDEX(Inputs!$C$22:$C$37,MATCH(C$4,Inputs!$A$22:$A$37,0))) -> Nylon
A8: Body yield (yd) | B8: =INDEX(Inputs!$D$22:$D$37,MATCH(B$4,Inputs!$A$22:$A$37,0)) -> 1.63 | C8: =INDEX(Inputs!$D$22:$D$37,MATCH(C$4,Inputs!$A$22:$A$37,0)) -> 1.4
A9: Body fabric price ($/yd) | B9: =IF(B7="",0,INDEX(Inputs!$B$6:$B$13,MATCH(B7,Inputs!$A$6:$A$13,0))) -> 0 | C9: =IF(C7="",0,INDEX(Inputs!$B$6:$B$13,MATCH(C7,Inputs!$A$6:$A$13,0))) -> 0
A10: Body fabric cost ($) | B10: =B8*B9 -> 0 | C10: =C8*C9 -> 0
A11: RIB
A12: Rib fabric | B12: =IF(INDEX(Inputs!$E$22:$E$37,MATCH(B$4,Inputs!$A$22:$A$37,0))="","",INDEX(Inputs!$E$22:$E$37,MATCH(B$4,Inputs!$A$22:$A$37,0))) | C12: =IF(INDEX(Inputs!$E$22:$E$37,MATCH(C$4,Inputs!$A$22:$A$37,0))="","",INDEX(Inputs!$E$22:$E$37,MATCH(C$4,Inputs!$A$22:$A$37,0)))
A13: Rib yield (yd) | B13: =INDEX(Inputs!$F$22:$F$37,MATCH(B$4,Inputs!$A$22:$A$37,0)) -> 0 | C13: =INDEX(Inputs!$F$22:$F$37,MATCH(C$4,Inputs!$A$22:$A$37,0)) -> 0
A14: Rib price ($/yd) | B14: =IF(B12="",0,INDEX(Inputs!$B$6:$B$13,MATCH(B12,Inputs!$A$6:$A$13,0))) -> 0 | C14: =IF(C12="",0,INDEX(Inputs!$B$6:$B$13,MATCH(C12,Inputs!$A$6:$A$13,0))) -> 0
A15: Rib cost ($) | B15: =B13*B14 -> 0 | C15: =C13*C14 -> 0
A16: DRAWSTRING & ELASTIC
A17: Drawstring (yd) | B17: =INDEX(Inputs!$G$22:$G$37,MATCH(B$4,Inputs!$A$22:$A$37,0)) -> 0 | C17: =INDEX(Inputs!$G$22:$G$37,MATCH(C$4,Inputs!$A$22:$A$37,0)) -> 0
A18: Drawstring price ($/yd) | B18: =Inputs!$B$17 -> 0.55 | C18: =Inputs!$B$17 -> 0.55
A19: Drawstring cost ($) | B19: =B17*B18 -> 0 | C19: =C17*C18 -> 0
A20: Elastic (yd) | B20: =INDEX(Inputs!$H$22:$H$37,MATCH(B$4,Inputs!$A$22:$A$37,0)) -> 0 | C20: =INDEX(Inputs!$H$22:$H$37,MATCH(C$4,Inputs!$A$22:$A$37,0)) -> 1.5
A21: Elastic price ($/yd) | B21: =Inputs!$B$18 -> 1 | C21: =Inputs!$B$18 -> 1
A22: Elastic cost ($) | B22: =B20*B21 -> 0 | C22: =C20*C21 -> 1.5
